Workbook
Name Plan1_Ano: Plan1!$A$2:$A$20000
Name Plan1_Etapas: Plan1!$N$2:$R$20000
Name Plan1_Faixas: Plan1!$H$2:$L$20000
Name Plan1_Municipio: Plan1!$D$2:$D$20000
Name Plan1_Rede: Plan1!$F$2:$F$20000

Sheet Consulta Faixa Etária
A1: Município: | B1: Todos os municípios | F1: ← escolha o município e a seleção nas listas. MÉDIA = 2016 a 2025. | N1: Auxiliares (não editar)
A2: Faixa etária: | B2: Todas as faixas (0 a 17 anos) | F2: Equivalências: 0-3 ≈ Creche · 4-5 ≈ Pré-escola · 6-10 ≈ Anos Iniciais · 11-14 ≈ Anos Finais · 15-17 ≈ Ensino Médio | N2: Índice da seleção | O2: =MATCH($B$2,Listas!$C$2:$C$7,0) -> 1
A3: População: | B3: =IF($B$1="Todos os municípios",SUM(População!$C$2:$C$400),INDEX(População!$C$2:$C$400,MATCH($B$1,População!$B$2:$B$400,0))) -> 11824665 | F3: ← população estimada 2024 | N3: Critério município | O3: =IF($B$1="Todos os municípios","*",$B$1) -> *
B4: PÚBLICO | C4: PUB. PERC | D4: FEDERAL | E4: FED. PERC | F4: ESTADUAL | G4: EST. PERC | H4: MUNICIPAL | I4: MUN. PERC | J4: PRIVADO | K4: PRI. PERC | L4: TOTAL | N4: Índice da rede (gráfico) | O4: =MATCH($B$16,Listas!$G$2:$G$7,0) -> 6
A5: 2016 | B5: =D5+F5+H5 -> 1918461 | C5: =IF($L5=0,0,B5/$L5) -> 0.83084573 | D5: =IF($O$2=1,SUMIFS(INDEX(Plan1_Faixas,0,1),Plan1_Ano,$A5,Plan1_Municipio,$O$3,Plan1_Rede,"Federal")+SUMIFS(INDEX(Plan1_Faixas,0,2),Plan1_Ano,$A5,Plan1_Municipio,$O$3,Plan1_Rede,"Federal")+SUMIFS(INDEX(Plan1_Faixas,0,3),Plan1_Ano,$A5,Plan1_Municipio,$O$3,Plan1_Rede,"Federal")+SUMIFS(INDEX(Plan1_Faixas,0,4),Plan1_Ano,$A5,Plan1_Municipio,$O$3,Plan1_Rede,"Federal")+SUMIFS(INDEX(Plan1_Faixas,0,5),Plan1_Ano,$A5,Plan1_Municipio,$O$3,Plan1_Rede,"Federal"),SUMIFS(INDEX(Plan1_Faixas,0,$O$2-1),Plan1_Ano,$A5,Plan1_Municipio,$O$3,Plan1_Rede,"Federal")) -> 6624 | E5: =IF($L5=0,0,D5/$L5) -> 0.0028687172 | F5: =IF($O$2=1,SUMIFS(INDEX(Plan1_Faixas,0,1),Plan1_Ano,$A5,Plan1_Municipio,$O$3,Plan1_Rede,"Estadual")+SUMIFS(INDEX(Plan1_Faixas,0,2),Plan1_Ano,$A5,Plan1_Municipio,$O$3,Plan1_Rede,"Estadual")+SUMIFS(INDEX(Plan1_Faixas,0,3),Plan1_Ano,$A5,Plan1_Municipio,$O$3,Plan1_Rede,"Estadual")+SUMIFS(INDEX(Plan1_Faixas,0,4),Plan1_Ano,$A5,Plan1_Municipio,$O$3,Plan1_Rede,"Estadual")+SUMIFS(INDEX(Plan1_Faixas,0,5),Plan1_Ano,$A5,Plan1_Municipio,$O$3,Plan1_Rede,"Estadual"),SUMIFS(INDEX(Plan1_Faixas,0,$O$2-1),Plan1_Ano,$A5,Plan1_Municipio,$O$3,Plan1_Rede,"Estadual")) -> 889861 | G5: =IF($L5=0,0,F5/$L5) -> 0.38538037 | H5: =IF($O$2=1,SUMIFS(INDEX(Plan1_Faixas,0,1),Plan1_Ano,$A5,Plan1_Municipio,$O$3,Plan1_Rede,"Municipal")+SUMIFS(INDEX(Plan1_Faixas,0,2),Plan1_Ano,$A5,Plan1_Municipio,$O$3,Plan1_Rede,"Municipal")+SUMIFS(INDEX(Plan1_Faixas,0,3),Plan1_Ano,$A5,Plan1_Municipio,$O$3,Plan1_Rede,"Municipal")+SUMIFS(INDEX(Plan1_Faixas,0,4),Plan1_Ano,$A5,Plan1_Municipio,$O$3,Plan1_Rede,"Municipal")+SUMIFS(INDEX(Plan1_Faixas,0,5),Plan1_Ano,$A5,Plan1_Municipio,$O$3,Plan1_Rede,"Municipal"),SUMIFS(INDEX(Plan1_Faixas,0,$O$2-1),Plan1_Ano,$A5,Plan1_Municipio,$O$3,Plan1_Rede,"Municipal")) -> 1021976 | I5: =IF($L5=0,0,H5/$L5) -> 0.44259664 | J5: =IF($O$2=1,SUMIFS(INDEX(Plan1_Faixas,0,1),Plan1_Ano,$A5,Plan1_Municipio,$O$3,Plan1_Rede,"Privada")+SUMIFS(INDEX(Plan1_Faixas,0,2),Plan1_Ano,$A5,Plan1_Municipio,$O$3,Plan1_Rede,"Privada")+SUMIFS(INDEX(Plan1_Faixas,0,3),Plan1_Ano,$A5,Plan1_Municipio,$O$3,Plan1_Rede,"Privada")+SUMIFS(INDEX(Plan1_Faixas,0,4),Plan1_Ano,$A5,Plan1_Municipio,$O$3,Plan1_Rede,"Privada")+SUMIFS(INDEX(Plan1_Faixas,0,5),Plan1_Ano,$A5,Plan1_Municipio,$O$3,Plan1_Rede,"Privada"),SUMIFS(INDEX(Plan1_Faixas,0,$O$2-1),Plan1_Ano,$A5,Plan1_Municipio,$O$3,Plan1_Rede,"Privada")) -> 390585 | K5: =IF($L5=0,0,J5/$L5) -> 0.16915427 | L5: =B5+J5 -> 2309046
A6: 2017 | B6: =D6+F6+H6 -> 1921338 | C6: =IF($L6=0,0,B6/$L6) -> 0.83375014 | D6: =IF($O$2=1,SUMIFS(INDEX(Plan1_Faixas,0,1),Plan1_Ano,$A6,Plan1_Municipio,$O$3,Plan1_Rede,"Federal")+SUMIFS(INDEX(Plan1_Faixas,0,2),Plan1_Ano,$A6,Plan1_Municipio,$O$3,Plan1_Rede,"Federal")+SUMIFS(INDEX(Plan1_Faixas,0,3),Plan1_Ano,$A6,Plan1_Municipio,$O$3,Plan1_Rede,"Federal")+SUMIFS(INDEX(Plan1_Faixas,0,4),Plan1_Ano,$A6,Plan1_Municipio,$O$3,Plan1_Rede,"Federal")+SUMIFS(INDEX(Plan1_Faixas,0,5),Plan1_Ano,$A6,Plan1_Municipio,$O$3,Plan1_Rede,"Federal"),SUMIFS(INDEX(Plan1_Faixas,0,$O$2-1),Plan1_Ano,$A6,Plan1_Municipio,$O$3,Plan1_Rede,"Federal")) -> 7548 | E6: =IF($L6=0,0,D6/$L6) -> 0.0032753977 | F6: =IF($O$2=1,SUMIFS(INDEX(Plan1_Faixas,0,1),Plan1_Ano,$A6,Plan1_Municipio,$O$3,Plan1_Rede,"Estadual")+SUMIFS(INDEX(Plan1_Faixas,0,2),Plan1_Ano,$A6,Plan1_Municipio,$O$3,Plan1_Rede,"Estadual")+SUMIFS(INDEX(Plan1_Faixas,0,3),Plan1_Ano,$A6,Plan1_Municipio,$O$3,Plan1_Rede,"Estadual")+SUMIFS(INDEX(Plan1_Faixas,0,4),Plan1_Ano,$A6,Plan1_Municipio,$O$3,Plan1_Rede,"Estadual")+SUMIFS(INDEX(Plan1_Faixas,0,5),Plan1_Ano,$A6,Plan1_Municipio,$O$3,Plan1_Rede,"Estadual"),SUMIFS(INDEX(Plan1_Faixas,0,$O$2-1),Plan1_Ano,$A6,Plan1_Municipio,$O$3,Plan1_Rede,"Estadual")) -> 879431 | G6: =IF($L6=0,0,F6/$L6) -> 0.38162245 | H6: =IF($O$2=1,SUMIFS(INDEX(Plan1_Faixas,0,1),Plan1_Ano,$A6,Plan1_Municipio,$O$3,Plan1_Rede,"Municipal")+SUMIFS(INDEX(Plan1_Faixas,0,2),Plan1_Ano,$A6,Plan1_Municipio,$O$3,Plan1_Rede,"Municipal")+SUMIFS(INDEX(Plan1_Faixas,0,3),Plan1_Ano,$A6,Plan1_Municipio,$O$3,Plan1_Rede,"Municipal")+SUMIFS(INDEX(Plan1_Faixas,0,4),Plan1_Ano,$A6,Plan1_Municipio,$O$3,Plan1_Rede,"Municipal")+SUMIFS(INDEX(Plan1_Faixas,0,5),Plan1_Ano,$A6,Plan1_Municipio,$O$3,Plan1_Rede,"Municipal"),SUMIFS(INDEX(Plan1_Faixas,0,$O$2-1),Plan1_Ano,$A6,Plan1_Municipio,$O$3,Plan1_Rede,"Municipal")) -> 1034359 | I6: =IF($L6=0,0,H6/$L6) -> 0.44885229 | J6: =IF($O$2=1,SUMIFS(INDEX(Plan1_Faixas,0,1),Plan1_Ano,$A6,Plan1_Municipio,$O$3,Plan1_Rede,"Privada")+SUMIFS(INDEX(Plan1_Faixas,0,2),Plan1_Ano,$A6,Plan1_Municipio,$O$3,Plan1_Rede,"Privada")+SUMIFS(INDEX(Plan1_Faixas,0,3),Plan1_Ano,$A6,Plan1_Municipio,$O$3,Plan1_Rede,"Privada")+SUMIFS(INDEX(Plan1_Faixas,0,4),Plan1_Ano,$A6,Plan1_Municipio,$O$3,Plan1_Rede,"Privada")+SUMIFS(INDEX(Plan1_Faixas,0,5),Plan1_Ano,$A6,Plan1_Municipio,$O$3,Plan1_Rede,"Privada"),SUMIFS(INDEX(Plan1_Faixas,0,$O$2-1),Plan1_Ano,$A6,Plan1_Municipio,$O$3,Plan1_Rede,"Privada")) -> 383115 | K6: =IF($L6=0,0,J6/$L6) -> 0.16624986 | L6: =B6+J6 -> 2304453
A7: 2018 | B7: =D7+F7+H7 -> 1918493 | C7: =IF($L7=0,0,B7/$L7) -> 0.83365583 | D7: =IF($O$2=1,SUMIFS(INDEX(Plan1_Faixas,0,1),Plan1_Ano,$A7,Plan1_Municipio,$O$3,Plan1_Rede,"Federal")+SUMIFS(INDEX(Plan1_Faixas,0,2),Plan1_Ano,$A7,Plan1_Municipio,$O$3,Plan1_Rede,"Federal")+SUMIFS(INDEX(Plan1_Faixas,0,3),Plan1_Ano,$A7,Plan1_Municipio,$O$3,Plan1_Rede,"Federal")+SUMIFS(INDEX(Plan1_Faixas,0,4),Plan1_Ano,$A7,Plan1_Municipio,$O$3,Plan1_Rede,"Federal")+SUMIFS(INDEX(Plan1_Faixas,0,5),Plan1_Ano,$A7,Plan1_Municipio,$O$3,Plan1_Rede,"Federal"),SUMIFS(INDEX(Plan1_Faixas,0,$O$2-1),Plan1_Ano,$A7,Plan1_Municipio,$O$3,Plan1_Rede,"Federal")) -> 8414 | E7: =IF($L7=0,0,D7/$L7) -> 0.0036561927 | F7: =IF($O$2=1,SUMIFS(INDEX(Plan1_Faixas,0,1),Plan1_Ano,$A7,Plan1_Municipio,$O$3,Plan1_Rede,"Estadual")+SUMIFS(INDEX(Plan1_Faixas,0,2),Plan1_Ano,$A7,Plan1_Municipio,$O$3,Plan1_Rede,"Estadual")+SUMIFS(INDEX(Plan1_Faixas,0,3),Plan1_Ano,$A7,Plan1_Municipio,$O$3,Plan1_Rede,"Estadual")+SUMIFS(INDEX(Plan1_Faixas,0,4),Plan1_Ano,$A7,Plan1_Municipio,$O$3,Plan1_Rede,"Estadual")+SUMIFS(INDEX(Plan1_Faixas,0,5),Plan1_Ano,$A7,Plan1_Municipio,$O$3,Plan1_Rede,"Estadual"),SUMIFS(INDEX(Plan1_Faixas,0,$O$2-1),Plan1_Ano,$A7,Plan1_Municipio,$O$3,Plan1_Rede,"Estadual")) -> 864196 | G7: =IF($L7=0,0,F7/$L7) -> 0.37552497 | H7: =IF($O$2=1,SUMIFS(INDEX(Plan1_Faixas,0,1),Plan1_Ano,$A7,Plan1_Municipio,$O$3,Plan1_Rede,"Municipal")+SUMIFS(INDEX(Plan1_Faixas,0,2),Plan1_Ano,$A7,Plan1_Municipio,$O$3,Plan1_Rede,"Municipal")+SUMIFS(INDEX(Plan1_Faixas,0,3),Plan1_Ano,$A7,Plan1_Municipio,$O$3,Plan1_Rede,"Municipal")+SUMIFS(INDEX(Plan1_Faixas,0,4),Plan1_Ano,$A7,Plan1_Municipio,$O$3,Plan1_Rede,"Municipal")+SUMIFS(INDEX(Plan1_Faixas,0,5),Plan1_Ano,$A7,Plan1_Municipio,$O$3,Plan1_Rede,"Municipal"),SUMIFS(INDEX(Plan1_Faixas,0,$O$2-1),Plan1_Ano,$A7,Plan1_Municipio,$O$3,Plan1_Rede,"Municipal")) -> 1045883 | I7: =IF($L7=0,0,H7/$L7) -> 0.45447466 | J7: =IF($O$2=1,SUMIFS(INDEX(Plan1_Faixas,0,1),Plan1_Ano,$A7,Plan1_Municipio,$O$3,Plan1_Rede,"Privada")+SUMIFS(INDEX(Plan1_Faixas,0,2),Plan1_Ano,$A7,Plan1_Municipio,$O$3,Plan1_Rede,"Privada")+SUMIFS(INDEX(Plan1_Faixas,0,3),Plan1_Ano,$A7,Plan1_Municipio,$O$3,Plan1_Rede,"Privada")+SUMIFS(INDEX(Plan1_Faixas,0,4),Plan1_Ano,$A7,Plan1_Municipio,$O$3,Plan1_Rede,"Privada")+SUMIFS(INDEX(Plan1_Faixas,0,5),Plan1_Ano,$A7,Plan1_Municipio,$O$3,Plan1_Rede,"Privada"),SUMIFS(INDEX(Plan1_Faixas,0,$O$2-1),Plan1_Ano,$A7,Plan1_Municipio,$O$3,Plan1_Rede,"Privada")) -> 382808 | K7: =IF($L7=0,0,J7/$L7) -> 0.16634417 | L7: =B7+J7 -> 2301301
A8: 2019 | B8: =D8+F8+H8 -> 1906102 | C8: =IF($L8=0,0,B8/$L8) -> 0.83088766 | D8: =IF($O$2=1,SUMIFS(INDEX(Plan1_Faixas,0,1),Plan1_Ano,$A8,Plan1_Municipio,$O$3,Plan1_Rede,"Federal")+SUMIFS(INDEX(Plan1_Faixas,0,2),Plan1_Ano,$A8,Plan1_Municipio,$O$3,Plan1_Rede,"Federal")+SUMIFS(INDEX(Plan1_Faixas,0,3),Plan1_Ano,$A8,Plan1_Municipio,$O$3,Plan1_Rede,"Federal")+SUMIFS(INDEX(Plan1_Faixas,0,4),Plan1_Ano,$A8,Plan1_Municipio,$O$3,Plan1_Rede,"Federal")+SUMIFS(INDEX(Plan1_Faixas,0,5),Plan1_Ano,$A8,Plan1_Municipio,$O$3,Plan1_Rede,"Federal"),SUMIFS(INDEX(Plan1_Faixas,0,$O$2-1),Plan1_Ano,$A8,Plan1_Municipio,$O$3,Plan1_Rede,"Federal")) -> 8413 | E8: =IF($L8=0,0,D8/$L8) -> 0.0036673053 | F8: =IF($O$2=1,SUMIFS(INDEX(Plan1_Faixas,0,1),Plan1_Ano,$A8,Plan1_Municipio,$O$3,Plan1_Rede,"Estadual")+SUMIFS(INDEX(Plan1_Faixas,0,2),Plan1_Ano,$A8,Plan1_Municipio,$O$3,Plan1_Rede,"Estadual")+SUMIFS(INDEX(Plan1_Faixas,0,3),Plan1_Ano,$A8,Plan1_Municipio,$O$3,Plan1_Rede,"Estadual")+SUMIFS(INDEX(Plan1_Faixas,0,4),Plan1_Ano,$A8,Plan1_Municipio,$O$3,Plan1_Rede,"Estadual")+SUMIFS(INDEX(Plan1_Faixas,0,5),Plan1_Ano,$A8,Plan1_Municipio,$O$3,Plan1_Rede,"Estadual"),SUMIFS(INDEX(Plan1_Faixas,0,$O$2-1),Plan1_Ano,$A8,Plan1_Municipio,$O$3,Plan1_Rede,"Estadual")) -> 851334 | G8: =IF($L8=0,0,F8/$L8) -> 0.37110444 | H8: =IF($O$2=1,SUMIFS(INDEX(Plan1_Faixas,0,1),Plan1_Ano,$A8,Plan1_Municipio,$O$3,Plan1_Rede,"Municipal")+SUMIFS(INDEX(Plan1_Faixas,0,2),Plan1_Ano,$A8,Plan1_Municipio,$O$3,Plan1_Rede,"Municipal")+SUMIFS(INDEX(Plan1_Faixas,0,3),Plan1_Ano,$A8,Plan1_Municipio,$O$3,Plan1_Rede,"Municipal")+SUMIFS(INDEX(Plan1_Faixas,0,4),Plan1_Ano,$A8,Plan1_Municipio,$O$3,Plan1_Rede,"Municipal")+SUMIFS(INDEX(Plan1_Faixas,0,5),Plan1_Ano,$A8,Plan1_Municipio,$O$3,Plan1_Rede,"Municipal"),SUMIFS(INDEX(Plan1_Faixas,0,$O$2-1),Plan1_Ano,$A8,Plan1_Municipio,$O$3,Plan1_Rede,"Municipal")) -> 1046355 | I8: =IF($L8=0,0,H8/$L8) -> 0.45611592 | J8: =IF($O$2=1,SUMIFS(INDEX(Plan1_Faixas,0,1),Plan1_Ano,$A8,Plan1_Municipio,$O$3,Plan1_Rede,"Privada")+SUMIFS(INDEX(Plan1_Faixas,0,2),Plan1_Ano,$A8,Plan1_Municipio,$O$3,Plan1_Rede,"Privada")+SUMIFS(INDEX(Plan1_Faixas,0,3),Plan1_Ano,$A8,Plan1_Municipio,$O$3,Plan1_Rede,"Privada")+SUMIFS(INDEX(Plan1_Faixas,0,4),Plan1_Ano,$A8,Plan1_Municipio,$O$3,Plan1_Rede,"Privada")+SUMIFS(INDEX(Plan1_Faixas,0,5),Plan1_Ano,$A8,Plan1_Municipio,$O$3,Plan1_Rede,"Privada"),SUMIFS(INDEX(Plan1_Faixas,0,$O$2-1),Plan1_Ano,$A8,Plan1_Municipio,$O$3,Plan1_Rede,"Privada")) -> 387953 | K8: =IF($L8=0,0,J8/$L8) -> 0.16911234 | L8: =B8+J8 -> 2294055
A9: 2020 | B9: =D9+F9+H9 -> 1922875 | C9: =IF($L9=0,0,B9/$L9) -> 0.83615076 | D9: =IF($O$2=1,SUMIFS(INDEX(Plan1_Faixas,0,1),Plan1_Ano,$A9,Plan1_Municipio,$O$3,Plan1_Rede,"Federal")+SUMIFS(INDEX(Plan1_Faixas,0,2),Plan1_Ano,$A9,Plan1_Municipio,$O$3,Plan1_Rede,"Federal")+SUMIFS(INDEX(Plan1_Faixas,0,3),Plan1_Ano,$A9,Plan1_Municipio,$O$3,Plan1_Rede,"Federal")+SUMIFS(INDEX(Plan1_Faixas,0,4),Plan1_Ano,$A9,Plan1_Municipio,$O$3,Plan1_Rede,"Federal")+SUMIFS(INDEX(Plan1_Faixas,0,5),Plan1_Ano,$A9,Plan1_Municipio,$O$3,Plan1_Rede,"Federal"),SUMIFS(INDEX(Plan1_Faixas,0,$O$2-1),Plan1_Ano,$A9,Plan1_Municipio,$O$3,Plan1_Rede,"Federal")) -> 8158 | E9: =IF($L9=0,0,D9/$L9) -> 0.0035474578 | F9: =IF($O$2=1,SUMIFS(INDEX(Plan1_Faixas,0,1),Plan1_Ano,$A9,Plan1_Municipio,$O$3,Plan1_Rede,"Estadual")+SUMIFS(INDEX(Plan1_Faixas,0,2),Plan1_Ano,$A9,Plan1_Municipio,$O$3,Plan1_Rede,"Estadual")+SUMIFS(INDEX(Plan1_Faixas,0,3),Plan1_Ano,$A9,Plan1_Municipio,$O$3,Plan1_Rede,"Estadual")+SUMIFS(INDEX(Plan1_Faixas,0,4),Plan1_Ano,$A9,Plan1_Municipio,$O$3,Plan1_Rede,"Estadual")+SUMIFS(INDEX(Plan1_Faixas,0,5),Plan1_Ano,$A9,Plan1_Municipio,$O$3,Plan1_Rede,"Estadual"),SUMIFS(INDEX(Plan1_Faixas,0,$O$2-1),Plan1_Ano,$A9,Plan1_Municipio,$O$3,Plan1_Rede,"Estadual")) -> 864313 | G9: =IF($L9=0,0,F9/$L9) -> 0.37584137 | H9: =IF($O$2=1,SUMIFS(INDEX(Plan1_Faixas,0,1),Plan1_Ano,$A9,Plan1_Municipio,$O$3,Plan1_Rede,"Municipal")+SUMIFS(INDEX(Plan1_Faixas,0,2),Plan1_Ano,$A9,Plan1_Municipio,$O$3,Plan1_Rede,"Municipal")+SUMIFS(INDEX(Plan1_Faixas,0,3),Plan1_Ano,$A9,Plan1_Municipio,$O$3,Plan1_Rede,"Municipal")+SUMIFS(INDEX(Plan1_Faixas,0,4),Plan1_Ano,$A9,Plan1_Municipio,$O$3,Plan1_Rede,"Municipal")+SUMIFS(INDEX(Plan1_Faixas,0,5),Plan1_Ano,$A9,Plan1_Municipio,$O$3,Plan1_Rede,"Municipal"),SUMIFS(INDEX(Plan1_Faixas,0,$O$2-1),Plan1_Ano,$A9,Plan1_Municipio,$O$3,Plan1_Rede,"Municipal")) -> 1050404 | I9: =IF($L9=0,0,H9/$L9) -> 0.45676193 | J9: =IF($O$2=1,SUMIFS(INDEX(Plan1_Faixas,0,1),Plan1_Ano,$A9,Plan1_Municipio,$O$3,Plan1_Rede,"Privada")+SUMIFS(INDEX(Plan1_Faixas,0,2),Plan1_Ano,$A9,Plan1_Municipio,$O$3,Plan1_Rede,"Privada")+SUMIFS(INDEX(Plan1_Faixas,0,3),Plan1_Ano,$A9,Plan1_Municipio,$O$3,Plan1_Rede,"Privada")+SUMIFS(INDEX(Plan1_Faixas,0,4),Plan1_Ano,$A9,Plan1_Municipio,$O$3,Plan1_Rede,"Privada")+SUMIFS(INDEX(Plan1_Faixas,0,5),Plan1_Ano,$A9,Plan1_Municipio,$O$3,Plan1_Rede,"Privada"),SUMIFS(INDEX(Plan1_Faixas,0,$O$2-1),Plan1_Ano,$A9,Plan1_Municipio,$O$3,Plan1_Rede,"Privada")) -> 376800 | K9: =IF($L9=0,0,J9/$L9) -> 0.16384924 | L9: =B9+J9 -> 2299675
A10: 2021 | B10: =D10+F10+H10 -> 1825771 | C10: =IF($L10=0,0,B10/$L10) -> 0.8420746 | D10: =IF($O$2=1,SUMIFS(INDEX(Plan1_Faixas,0,1),Plan1_Ano,$A10,Plan1_Municipio,$O$3,Plan1_Rede,"Federal")+SUMIFS(INDEX(Plan1_Faixas,0,2),Plan1_Ano,$A10,Plan1_Municipio,$O$3,Plan1_Rede,"Federal")+SUMIFS(INDEX(Plan1_Faixas,0,3),Plan1_Ano,$A10,Plan1_Municipio,$O$3,Plan1_Rede,"Federal")+SUMIFS(INDEX(Plan1_Faixas,0,4),Plan1_Ano,$A10,Plan1_Municipio,$O$3,Plan1_Rede,"Federal")+SUMIFS(INDEX(Plan1_Faixas,0,5),Plan1_Ano,$A10,Plan1_Municipio,$O$3,Plan1_Rede,"Federal"),SUMIFS(INDEX(Plan1_Faixas,0,$O$2-1),Plan1_Ano,$A10,Plan1_Municipio,$O$3,Plan1_Rede,"Federal")) -> 6697 | E10: =IF($L10=0,0,D10/$L10) -> 0.0030887628 | F10: =IF($O$2=1,SUMIFS(INDEX(Plan1_Faixas,0,1),Plan1_Ano,$A10,Plan1_Municipio,$O$3,Plan1_Rede,"Estadual")+SUMIFS(INDEX(Plan1_Faixas,0,2),Plan1_Ano,$A10,Plan1_Municipio,$O$3,Plan1_Rede,"Estadual")+SUMIFS(INDEX(Plan1_Faixas,0,3),Plan1_Ano,$A10,Plan1_Municipio,$O$3,Plan1_Rede,"Estadual")+SUMIFS(INDEX(Plan1_Faixas,0,4),Plan1_Ano,$A10,Plan1_Municipio,$O$3,Plan1_Rede,"Estadual")+SUMIFS(INDEX(Plan1_Faixas,0,5),Plan1_Ano,$A10,Plan1_Municipio,$O$3,Plan1_Rede,"Estadual"),SUMIFS(INDEX(Plan1_Faixas,0,$O$2-1),Plan1_Ano,$A10,Plan1_Municipio,$O$3,Plan1_Rede,"Estadual")) -> 780744 | G10: =IF($L10=0,0,F10/$L10) -> 0.36009154 | H10: =IF($O$2=1,SUMIFS(INDEX(Plan1_Faixas,0,1),Plan1_Ano,$A10,Plan1_Municipio,$O$3,Plan1_Rede,"Municipal")+SUMIFS(INDEX(Plan1_Faixas,0,2),Plan1_Ano,$A10,Plan1_Municipio,$O$3,Plan1_Rede,"Municipal")+SUMIFS(INDEX(Plan1_Faixas,0,3),Plan1_Ano,$A10,Plan1_Municipio,$O$3,Plan1_Rede,"Municipal")+SUMIFS(INDEX(Plan1_Faixas,0,4),Plan1_Ano,$A10,Plan1_Municipio,$O$3,Plan1_Rede,"Municipal")+SUMIFS(INDEX(Plan1_Faixas,0,5),Plan1_Ano,$A10,Plan1_Municipio,$O$3,Plan1_Rede,"Municipal"),SUMIFS(INDEX(Plan1_Faixas,0,$O$2-1),Plan1_Ano,$A10,Plan1_Municipio,$O$3,Plan1_Rede,"Municipal")) -> 1038330 | I10: =IF($L10=0,0,H10/$L10) -> 0.4788943 | J10: =IF($O$2=1,SUMIFS(INDEX(Plan1_Faixas,0,1),Plan1_Ano,$A10,Plan1_Municipio,$O$3,Plan1_Rede,"Privada")+SUMIFS(INDEX(Plan1_Faixas,0,2),Plan1_Ano,$A10,Plan1_Municipio,$O$3,Plan1_Rede,"Privada")+SUMIFS(INDEX(Plan1_Faixas,0,3),Plan1_Ano,$A10,Plan1_Municipio,$O$3,Plan1_Rede,"Privada")+SUMIFS(INDEX(Plan1_Faixas,0,4),Plan1_Ano,$A10,Plan1_Municipio,$O$3,Plan1_Rede,"Privada")+SUMIFS(INDEX(Plan1_Faixas,0,5),Plan1_Ano,$A10,Plan1_Municipio,$O$3,Plan1_Rede,"Privada"),SUMIFS(INDEX(Plan1_Faixas,0,$O$2-1),Plan1_Ano,$A10,Plan1_Municipio,$O$3,Plan1_Rede,"Privada")) -> 342411 | K10: =IF($L10=0,0,J10/$L10) -> 0.1579254 | L10: =B10+J10 -> 2168182
A11: 2022 | B11: =D11+F11+H11 -> 1921832 | C11: =IF($L11=0,0,B11/$L11) -> 0.83635185 | D11: =IF($O$2=1,SUMIFS(INDEX(Plan1_Faixas,0,1),Plan1_Ano,$A11,Plan1_Municipio,$O$3,Plan1_Rede,"Federal")+SUMIFS(INDEX(Plan1_Faixas,0,2),Plan1_Ano,$A11,Plan1_Municipio,$O$3,Plan1_Rede,"Federal")+SUMIFS(INDEX(Plan1_Faixas,0,3),Plan1_Ano,$A11,Plan1_Municipio,$O$3,Plan1_Rede,"Federal")+SUMIFS(INDEX(Plan1_Faixas,0,4),Plan1_Ano,$A11,Plan1_Municipio,$O$3,Plan1_Rede,"Federal")+SUMIFS(INDEX(Plan1_Faixas,0,5),Plan1_Ano,$A11,Plan1_Municipio,$O$3,Plan1_Rede,"Federal"),SUMIFS(INDEX(Plan1_Faixas,0,$O$2-1),Plan1_Ano,$A11,Plan1_Municipio,$O$3,Plan1_Rede,"Federal")) -> 7074 | E11: =IF($L11=0,0,D11/$L11) -> 0.0030784964 | F11: =IF($O$2=1,SUMIFS(INDEX(Plan1_Faixas,0,1),Plan1_Ano,$A11,Plan1_Municipio,$O$3,Plan1_Rede,"Estadual")+SUMIFS(INDEX(Plan1_Faixas,0,2),Plan1_Ano,$A11,Plan1_Municipio,$O$3,Plan1_Rede,"Estadual")+SUMIFS(INDEX(Plan1_Faixas,0,3),Plan1_Ano,$A11,Plan1_Municipio,$O$3,Plan1_Rede,"Estadual")+SUMIFS(INDEX(Plan1_Faixas,0,4),Plan1_Ano,$A11,Plan1_Municipio,$O$3,Plan1_Rede,"Estadual")+SUMIFS(INDEX(Plan1_Faixas,0,5),Plan1_Ano,$A11,Plan1_Municipio,$O$3,Plan1_Rede,"Estadual"),SUMIFS(INDEX(Plan1_Faixas,0,$O$2-1),Plan1_Ano,$A11,Plan1_Municipio,$O$3,Plan1_Rede,"Estadual")) -> 857434 | G11: =IF($L11=0,0,F11/$L11) -> 0.37314214 | H11: =IF($O$2=1,SUMIFS(INDEX(Plan1_Faixas,0,1),Plan1_Ano,$A11,Plan1_Municipio,$O$3,Plan1_Rede,"Municipal")+SUMIFS(INDEX(Plan1_Faixas,0,2),Plan1_Ano,$A11,Plan1_Municipio,$O$3,Plan1_Rede,"Municipal")+SUMIFS(INDEX(Plan1_Faixas,0,3),Plan1_Ano,$A11,Plan1_Municipio,$O$3,Plan1_Rede,"Municipal")+SUMIFS(INDEX(Plan1_Faixas,0,4),Plan1_Ano,$A11,Plan1_Municipio,$O$3,Plan1_Rede,"Municipal")+SUMIFS(INDEX(Plan1_Faixas,0,5),Plan1_Ano,$A11,Plan1_Municipio,$O$3,Plan1_Rede,"Municipal"),SUMIFS(INDEX(Plan1_Faixas,0,$O$2-1),Plan1_Ano,$A11,Plan1_Municipio,$O$3,Plan1_Rede,"Municipal")) -> 1057324 | I11: =IF($L11=0,0,H11/$L11) -> 0.46013121 | J11: =IF($O$2=1,SUMIFS(INDEX(Plan1_Faixas,0,1),Plan1_Ano,$A11,Plan1_Municipio,$O$3,Plan1_Rede,"Privada")+SUMIFS(INDEX(Plan1_Faixas,0,2),Plan1_Ano,$A11,Plan1_Municipio,$O$3,Plan1_Rede,"Privada")+SUMIFS(INDEX(Plan1_Faixas,0,3),Plan1_Ano,$A11,Plan1_Municipio,$O$3,Plan1_Rede,"Privada")+SUMIFS(INDEX(Plan1_Faixas,0,4),Plan1_Ano,$A11,Plan1_Municipio,$O$3,Plan1_Rede,"Privada")+SUMIFS(INDEX(Plan1_Faixas,0,5),Plan1_Ano,$A11,Plan1_Municipio,$O$3,Plan1_Rede,"Privada"),SUMIFS(INDEX(Plan1_Faixas,0,$O$2-1),Plan1_Ano,$A11,Plan1_Municipio,$O$3,Plan1_Rede,"Privada")) -> 376043 | K11: =IF($L11=0,0,J11/$L11) -> 0.16364815 | L11: =B11+J11 -> 2297875
A12: 2023 | B12: =D12+F12+H12 -> 1908313 | C12: =IF($L12=0,0,B12/$L12) -> 0.82999397 | D12: =IF($O$2=1,SUMIFS(INDEX(Plan1_Faixas,0,1),Plan1_Ano,$A12,Plan1_Municipio,$O$3,Plan1_Rede,"Federal")+SUMIFS(INDEX(Plan1_Faixas,0,2),Plan1_Ano,$A12,Plan1_Municipio,$O$3,Plan1_Rede,"Federal")+SUMIFS(INDEX(Plan1_Faixas,0,3),Plan1_Ano,$A12,Plan1_Municipio,$O$3,Plan1_Rede,"Federal")+SUMIFS(INDEX(Plan1_Faixas,0,4),Plan1_Ano,$A12,Plan1_Municipio,$O$3,Plan1_Rede,"Federal")+SUMIFS(INDEX(Plan1_Faixas,0,5),Plan1_Ano,$A12,Plan1_Municipio,$O$3,Plan1_Rede,"Federal"),SUMIFS(INDEX(Plan1_Faixas,0,$O$2-1),Plan1_Ano,$A12,Plan1_Municipio,$O$3,Plan1_Rede,"Federal")) -> 7213 | E12: =IF($L12=0,0,D12/$L12) -> 0.0031371932 | F12: =IF($O$2=1,SUMIFS(INDEX(Plan1_Faixas,0,1),Plan1_Ano,$A12,Plan1_Municipio,$O$3,Plan1_Rede,"Estadual")+SUMIFS(INDEX(Plan1_Faixas,0,2),Plan1_Ano,$A12,Plan1_Municipio,$O$3,Plan1_Rede,"Estadual")+SUMIFS(INDEX(Plan1_Faixas,0,3),Plan1_Ano,$A12,Plan1_Municipio,$O$3,Plan1_Rede,"Estadual")+SUMIFS(INDEX(Plan1_Faixas,0,4),Plan1_Ano,$A12,Plan1_Municipio,$O$3,Plan1_Rede,"Estadual")+SUMIFS(INDEX(Plan1_Faixas,0,5),Plan1_Ano,$A12,Plan1_Municipio,$O$3,Plan1_Rede,"Estadual"),SUMIFS(INDEX(Plan1_Faixas,0,$O$2-1),Plan1_Ano,$A12,Plan1_Municipio,$O$3,Plan1_Rede,"Estadual")) -> 820973 | G12: =IF($L12=0,0,F12/$L12) -> 0.35707069 | H12: =IF($O$2=1,SUMIFS(INDEX(Plan1_Faixas,0,1),Plan1_Ano,$A12,Plan1_Municipio,$O$3,Plan1_Rede,"Municipal")+SUMIFS(INDEX(Plan1_Faixas,0,2),Plan1_Ano,$A12,Plan1_Municipio,$O$3,Plan1_Rede,"Municipal")+SUMIFS(INDEX(Plan1_Faixas,0,3),Plan1_Ano,$A12,Plan1_Municipio,$O$3,Plan1_Rede,"Municipal")+SUMIFS(INDEX(Plan1_Faixas,0,4),Plan1_Ano,$A12,Plan1_Municipio,$O$3,Plan1_Rede,"Municipal")+SUMIFS(INDEX(Plan1_Faixas,0,5),Plan1_Ano,$A12,Plan1_Municipio,$O$3,Plan1_Rede,"Municipal"),SUMIFS(INDEX(Plan1_Faixas,0,$O$2-1),Plan1_Ano,$A12,Plan1_Municipio,$O$3,Plan1_Rede,"Municipal")) -> 1080127 | I12: =IF($L12=0,0,H12/$L12) -> 0.46978609 | J12: =IF($O$2=1,SUMIFS(INDEX(Plan1_Faixas,0,1),Plan1_Ano,$A12,Plan1_Municipio,$O$3,Plan1_Rede,"Privada")+SUMIFS(INDEX(Plan1_Faixas,0,2),Plan1_Ano,$A12,Plan1_Municipio,$O$3,Plan1_Rede,"Privada")+SUMIFS(INDEX(Plan1_Faixas,0,3),Plan1_Ano,$A12,Plan1_Municipio,$O$3,Plan1_Rede,"Privada")+SUMIFS(INDEX(Plan1_Faixas,0,4),Plan1_Ano,$A12,Plan1_Municipio,$O$3,Plan1_Rede,"Privada")+SUMIFS(INDEX(Plan1_Faixas,0,5),Plan1_Ano,$A12,Plan1_Municipio,$O$3,Plan1_Rede,"Privada"),SUMIFS(INDEX(Plan1_Faixas,0,$O$2-1),Plan1_Ano,$A12,Plan1_Municipio,$O$3,Plan1_Rede,"Privada")) -> 390876 | K12: =IF($L12=0,0,J12/$L12) -> 0.17000603 | L12: =B12+J12 -> 2299189
A13: 2024 | B13: =D13+F13+H13 -> 1932608 | C13: =IF($L13=0,0,B13/$L13) -> 0.82757475 | D13: =IF($O$2=1,SUMIFS(INDEX(Plan1_Faixas,0,1),Plan1_Ano,$A13,Plan1_Municipio,$O$3,Plan1_Rede,"Federal")+SUMIFS(INDEX(Plan1_Faixas,0,2),Plan1_Ano,$A13,Plan1_Municipio,$O$3,Plan1_Rede,"Federal")+SUMIFS(INDEX(Plan1_Faixas,0,3),Plan1_Ano,$A13,Plan1_Municipio,$O$3,Plan1_Rede,"Federal")+SUMIFS(INDEX(Plan1_Faixas,0,4),Plan1_Ano,$A13,Plan1_Municipio,$O$3,Plan1_Rede,"Federal")+SUMIFS(INDEX(Plan1_Faixas,0,5),Plan1_Ano,$A13,Plan1_Municipio,$O$3,Plan1_Rede,"Federal"),SUMIFS(INDEX(Plan1_Faixas,0,$O$2-1),Plan1_Ano,$A13,Plan1_Municipio,$O$3,Plan1_Rede,"Federal")) -> 7899 | E13: =IF($L13=0,0,D13/$L13) -> 0.0033824826 | F13: =IF($O$2=1,SUMIFS(INDEX(Plan1_Faixas,0,1),Plan1_Ano,$A13,Plan1_Municipio,$O$3,Plan1_Rede,"Estadual")+SUMIFS(INDEX(Plan1_Faixas,0,2),Plan1_Ano,$A13,Plan1_Municipio,$O$3,Plan1_Rede,"Estadual")+SUMIFS(INDEX(Plan1_Faixas,0,3),Plan1_Ano,$A13,Plan1_Municipio,$O$3,Plan1_Rede,"Estadual")+SUMIFS(INDEX(Plan1_Faixas,0,4),Plan1_Ano,$A13,Plan1_Municipio,$O$3,Plan1_Rede,"Estadual")+SUMIFS(INDEX(Plan1_Faixas,0,5),Plan1_Ano,$A13,Plan1_Municipio,$O$3,Plan1_Rede,"Estadual"),SUMIFS(INDEX(Plan1_Faixas,0,$O$2-1),Plan1_Ano,$A13,Plan1_Municipio,$O$3,Plan1_Rede,"Estadual")) -> 832822 | G13: =IF($L13=0,0,F13/$L13) -> 0.35662817 | H13: =IF($O$2=1,SUMIFS(INDEX(Plan1_Faixas,0,1),Plan1_Ano,$A13,Plan1_Municipio,$O$3,Plan1_Rede,"Municipal")+SUMIFS(INDEX(Plan1_Faixas,0,2),Plan1_Ano,$A13,Plan1_Municipio,$O$3,Plan1_Rede,"Municipal")+SUMIFS(INDEX(Plan1_Faixas,0,3),Plan1_Ano,$A13,Plan1_Municipio,$O$3,Plan1_Rede,"Municipal")+SUMIFS(INDEX(Plan1_Faixas,0,4),Plan1_Ano,$A13,Plan1_Municipio,$O$3,Plan1_Rede,"Municipal")+SUMIFS(INDEX(Plan1_Faixas,0,5),Plan1_Ano,$A13,Plan1_Municipio,$O$3,Plan1_Rede,"Municipal"),SUMIFS(INDEX(Plan1_Faixas,0,$O$2-1),Plan1_Ano,$A13,Plan1_Municipio,$O$3,Plan1_Rede,"Municipal")) -> 1091887 | I13: =IF($L13=0,0,H13/$L13) -> 0.46756409 | J13: =IF($O$2=1,SUMIFS(INDEX(Plan1_Faixas,0,1),Plan1_Ano,$A13,Plan1_Municipio,$O$3,Plan1_Rede,"Privada")+SUMIFS(INDEX(Plan1_Faixas,0,2),Plan1_Ano,$A13,Plan1_Municipio,$O$3,Plan1_Rede,"Privada")+SUMIFS(INDEX(Plan1_Faixas,0,3),Plan1_Ano,$A13,Plan1_Municipio,$O$3,Plan1_Rede,"Privada")+SUMIFS(INDEX(Plan1_Faixas,0,4),Plan1_Ano,$A13,Plan1_Municipio,$O$3,Plan1_Rede,"Privada")+SUMIFS(INDEX(Plan1_Faixas,0,5),Plan1_Ano,$A13,Plan1_Municipio,$O$3,Plan1_Rede,"Privada"),SUMIFS(INDEX(Plan1_Faixas,0,$O$2-1),Plan1_Ano,$A13,Plan1_Municipio,$O$3,Plan1_Rede,"Privada")) -> 402659 | K13: =IF($L13=0,0,J13/$L13) -> 0.17242525 | L13: =B13+J13 -> 2335267
A14: 2025 | B14: =D14+F14+H14 -> 1887071 | C14: =IF($L14=0,0,B14/$L14) -> 0.8233682 | D14: =IF($O$2=1,SUMIFS(INDEX(Plan1_Faixas,0,1),Plan1_Ano,$A14,Plan1_Municipio,$O$3,Plan1_Rede,"Federal")+SUMIFS(INDEX(Plan1_Faixas,0,2),Plan1_Ano,$A14,Plan1_Municipio,$O$3,Plan1_Rede,"Federal")+SUMIFS(INDEX(Plan1_Faixas,0,3),Plan1_Ano,$A14,Plan1_Municipio,$O$3,Plan1_Rede,"Federal")+SUMIFS(INDEX(Plan1_Faixas,0,4),Plan1_Ano,$A14,Plan1_Municipio,$O$3,Plan1_Rede,"Federal")+SUMIFS(INDEX(Plan1_Faixas,0,5),Plan1_Ano,$A14,Plan1_Municipio,$O$3,Plan1_Rede,"Federal"),SUMIFS(INDEX(Plan1_Faixas,0,$O$2-1),Plan1_Ano,$A14,Plan1_Municipio,$O$3,Plan1_Rede,"Federal")) -> 8380 | E14: =IF($L14=0,0,D14/$L14) -> 0.0036563678 | F14: =IF($O$2=1,SUMIFS(INDEX(Plan1_Faixas,0,1),Plan1_Ano,$A14,Plan1_Municipio,$O$3,Plan1_Rede,"Estadual")+SUMIFS(INDEX(Plan1_Faixas,0,2),Plan1_Ano,$A14,Plan1_Municipio,$O$3,Plan1_Rede,"Estadual")+SUMIFS(INDEX(Plan1_Faixas,0,3),Plan1_Ano,$A14,Plan1_Municipio,$O$3,Plan1_Rede,"Estadual")+SUMIFS(INDEX(Plan1_Faixas,0,4),Plan1_Ano,$A14,Plan1_Municipio,$O$3,Plan1_Rede,"Estadual")+SUMIFS(INDEX(Plan1_Faixas,0,5),Plan1_Ano,$A14,Plan1_Municipio,$O$3,Plan1_Rede,"Estadual"),SUMIFS(INDEX(Plan1_Faixas,0,$O$2-1),Plan1_Ano,$A14,Plan1_Municipio,$O$3,Plan1_Rede,"Estadual")) -> 788833 | G14: =IF($L14=0,0,F14/$L14) -> 0.34418419 | H14: =IF($O$2=1,SUMIFS(INDEX(Plan1_Faixas,0,1),Plan1_Ano,$A14,Plan1_Municipio,$O$3,Plan1_Rede,"Municipal")+SUMIFS(INDEX(Plan1_Faixas,0,2),Plan1_Ano,$A14,Plan1_Municipio,$O$3,Plan1_Rede,"Municipal")+SUMIFS(INDEX(Plan1_Faixas,0,3),Plan1_Ano,$A14,Plan1_Municipio,$O$3,Plan1_Rede,"Municipal")+SUMIFS(INDEX(Plan1_Faixas,0,4),Plan1_Ano,$A14,Plan1_Municipio,$O$3,Plan1_Rede,"Municipal")+SUMIFS(INDEX(Plan1_Faixas,0,5),Plan1_Ano,$A14,Plan1_Municipio,$O$3,Plan1_Rede,"Municipal"),SUMIFS(INDEX(Plan1_Faixas,0,$O$2-1),Plan1_Ano,$A14,Plan1_Municipio,$O$3,Plan1_Rede,"Municipal")) -> 1089858 | I14: =IF($L14=0,0,H14/$L14) -> 0.47552764 | J14: =IF($O$2=1,SUMIFS(INDEX(Plan1_Faixas,0,1),Plan1_Ano,$A14,Plan1_Municipio,$O$3,Plan1_Rede,"Privada")+SUMIFS(INDEX(Plan1_Faixas,0,2),Plan1_Ano,$A14,Plan1_Municipio,$O$3,Plan1_Rede,"Privada")+SUMIFS(INDEX(Plan1_Faixas,0,3),Plan1_Ano,$A14,Plan1_Municipio,$O$3,Plan1_Rede,"Privada")+SUMIFS(INDEX(Plan1_Faixas,0,4),Plan1_Ano,$A14,Plan1_Municipio,$O$3,Plan1_Rede,"Privada")+SUMIFS(INDEX(Plan1_Faixas,0,5),Plan1_Ano,$A14,Plan1_Municipio,$O$3,Plan1_Rede,"Privada"),SUMIFS(INDEX(Plan1_Faixas,0,$O$2-1),Plan1_Ano,$A14,Plan1_Municipio,$O$3,Plan1_Rede,"Privada")) -> 404821 | K14: =IF($L14=0,0,J14/$L14) -> 0.1766318 | L14: =B14+J14 -> 2291892
A15: MÉDIA | B15: =AVERAGE(B5:B14) -> 1906286.4 | C15: =IF($L15=0,0,B15/$L15) -> 0.83240549 | D15: =AVERAGE(D5:D14) -> 7642 | E15: =IF($L15=0,0,D15/$L15) -> 0.0033369817 | F15: =AVERAGE(F5:F14) -> 842994.1 | G15: =IF($L15=0,0,F15/$L15) -> 0.36810466 | H15: =AVERAGE(H5:H14) -> 1055650.3 | I15: =IF($L15=0,0,H15/$L15) -> 0.46096384 | J15: =AVERAGE(J5:J14) -> 383807.1 | K15: =IF($L15=0,0,J15/$L15) -> 0.16759451 | L15: =AVERAGE(L5:L14) -> 2290093.5
A16: Rede do gráfico: | B16: Total | F16: ="Variação anual da rede "&LOWER($B$16)&" — "&$B$1&" — "&$B$2 -> Variação anual da rede total — Todos os municípios — Todas as faixas (0 a 17 anos)
A39: Variação anual das matrículas (%) em relação ao ano anterior
A40: Ano | B40: PÚBLICO | C40: FEDERAL | D40: ESTADUAL | E40: MUNICIPAL | F40: PRIVADO | G40: TOTAL
A41: 2016 | B41: — | C41: — | D41: — | E41: — | F41: — | G41: —
A42: 2017 | B42: =IF(B5=0,"—",B6/B5-1) -> 0.0014996396 | C42: =IF(D5=0,"—",D6/D5-1) -> 0.13949275 | D42: =IF(F5=0,"—",F6/F5-1) -> -0.011720932 | E42: =IF(H5=0,"—",H6/H5-1) -> 0.012116723 | F42: =IF(J5=0,"—",J6/J5-1) -> -0.019125158 | G42: =IF(L5=0,"—",L6/L5-1) -> -0.0019891332
A43: 2018 | B43: =IF(B6=0,"—",B7/B6-1) -> -0.0014807389 | C43: =IF(D6=0,"—",D7/D6-1) -> 0.11473238 | D43: =IF(F6=0,"—",F7/F6-1) -> -0.017323701 | E43: =IF(H6=0,"—",H7/H6-1) -> 0.0111412 | F43: =IF(J6=0,"—",J7/J6-1) -> -0.00080132597 | G43: =IF(L6=0,"—",L7/L6-1) -> -0.0013677866
A44: 2019 | B44: =IF(B7=0,"—",B8/B7-1) -> -0.0064587153 | C44: =IF(D7=0,"—",D8/D7-1) -> -0.00011884954 | D44: =IF(F7=0,"—",F8/F7-1) -> -0.014883198 | E44: =IF(H7=0,"—",H8/H7-1) -> 0.00045129331 | F44: =IF(J7=0,"—",J8/J7-1) -> 0.013440158 | G44: =IF(L7=0,"—",L8/L7-1) -> -0.0031486537
A45: 2020 | B45: =IF(B8=0,"—",B9/B8-1) -> 0.008799634 | C45: =IF(D8=0,"—",D9/D8-1) -> -0.030310234 | D45: =IF(F8=0,"—",F9/F8-1) -> 0.015245485 | E45: =IF(H8=0,"—",H9/H8-1) -> 0.0038696236 | F45: =IF(J8=0,"—",J9/J8-1) -> -0.028748328 | G45: =IF(L8=0,"—",L9/L8-1) -> 0.0024498105
A46: 2021 | B46: =IF(B9=0,"—",B10/B9-1) -> -0.050499382 | C46: =IF(D9=0,"—",D10/D9-1) -> -0.17908801 | D46: =IF(F9=0,"—",F10/F9-1) -> -0.096688352 | E46: =IF(H9=0,"—",H10/H9-1) -> -0.011494625 | F46: =IF(J9=0,"—",J10/J9-1) -> -0.091265924 | G46: =IF(L9=0,"—",L10/L9-1) -> -0.057178949
A47: 2022 | B47: =IF(B10=0,"—",B11/B10-1) -> 0.052613937 | C47: =IF(D10=0,"—",D11/D10-1) -> 0.056293863 | D47: =IF(F10=0,"—",F11/F10-1) -> 0.09822682 | E47: =IF(H10=0,"—",H11/H10-1) -> 0.018292836 | F47: =IF(J10=0,"—",J11/J10-1) -> 0.098221144 | G47: =IF(L10=0,"—",L11/L10-1) -> 0.059816473
A48: 2023 | B48: =IF(B11=0,"—",B12/B11-1) -> -0.0070344338 | C48: =IF(D11=0,"—",D12/D11-1) -> 0.01964942 | D48: =IF(F11=0,"—",F12/F11-1) -> -0.04252339 | E48: =IF(H11=0,"—",H12/H11-1) -> 0.02156671 | F48: =IF(J11=0,"—",J12/J11-1) -> 0.039444957 | G48: =IF(L11=0,"—",L12/L11-1) -> 0.00057183267
A49: 2024 | B49: =IF(B12=0,"—",B13/B12-1) -> 0.01273114 | C49: =IF(D12=0,"—",D13/D12-1) -> 0.095106059 | D49: =IF(F12=0,"—",F13/F12-1) -> 0.014432874 | E49: =IF(H12=0,"—",H13/H12-1) -> 0.010887609 | F49: =IF(J12=0,"—",J13/J12-1) -> 0.03014511 | G49: =IF(L12=0,"—",L13/L12-1) -> 0.01569162
A50: 2025 | B50: =IF(B13=0,"—",B14/B13-1) -> -0.023562461 | C50: =IF(D13=0,"—",D14/D13-1) -> 0.060893784 | D50: =IF(F13=0,"—",F14/F13-1) -> -0.05281921 | E50: =IF(H13=0,"—",H14/H13-1) -> -0.0018582509 | F50: =IF(J13=0,"—",J14/J13-1) -> 0.0053693075 | G50: =IF(L13=0,"—",L14/L13-1) -> -0.018573893
A51: "—" = sem ano anterior ou rede sem matrículas no ano anterior.
A53: Dados do gráfico (rede selecionada em B16)
A54: Ano | B54: Matrículas | C54: Variação anual | D54: Crescimento | E54: Queda
A55: 2016 | B55: =CHOOSE($O$4,B5,D5,F5,H5,J5,L5) -> 2309046 | C55: — | D55: 0 | E55: 0
A56: 2017 | B56: =CHOOSE($O$4,B6,D6,F6,H6,J6,L6) -> 2304453 | C56: =IF(B55=0,0,B56/B55-1) -> -0.0019891332 | D56: =IF(C56>0,C56,0) -> 0 | E56: =IF(C56<0,C56,0) -> -0.0019891332
A57: 2018 | B57: =CHOOSE($O$4,B7,D7,F7,H7,J7,L7) -> 2301301 | C57: =IF(B56=0,0,B57/B56-1) -> -0.0013677866 | D57: =IF(C57>0,C57,0) -> 0 | E57: =IF(C57<0,C57,0) -> -0.0013677866
A58: 2019 | B58: =CHOOSE($O$4,B8,D8,F8,H8,J8,L8) -> 2294055 | C58: =IF(B57=0,0,B58/B57-1) -> -0.0031486537 | D58: =IF(C58>0,C58,0) -> 0 | E58: =IF(C58<0,C58,0) -> -0.0031486537
A59: 2020 | B59: =CHOOSE($O$4,B9,D9,F9,H9,J9,L9) -> 2299675 | C59: =IF(B58=0,0,B59/B58-1) -> 0.0024498105 | D59: =IF(C59>0,C59,0) -> 0.0024498105 | E59: =IF(C59<0,C59,0) -> 0
A60: 2021 | B60: =CHOOSE($O$4,B10,D10,F10,H10,J10,L10) -> 2168182 | C60: =IF(B59=0,0,B60/B59-1) -> -0.057178949 | D60: =IF(C60>0,C60,0) -> 0 | E60: =IF(C60<0,C60,0) -> -0.057178949
A61: 2022 | B61: =CHOOSE($O$4,B11,D11,F11,H11,J11,L11) -> 2297875 | C61: =IF(B60=0,0,B61/B60-1) -> 0.059816473 | D61: =IF(C61>0,C61,0) -> 0.059816473 | E61: =IF(C61<0,C61,0) -> 0
A62: 2023 | B62: =CHOOSE($O$4,B12,D12,F12,H12,J12,L12) -> 2299189 | C62: =IF(B61=0,0,B62/B61-1) -> 0.00057183267 | D62: =IF(C62>0,C62,0) -> 0.00057183267 | E62: =IF(C62<0,C62,0) -> 0
A63: 2024 | B63: =CHOOSE($O$4,B13,D13,F13,H13,J13,L13) -> 2335267 | C63: =IF(B62=0,0,B63/B62-1) -> 0.01569162 | D63: =IF(C63>0,C63,0) -> 0.01569162 | E63: =IF(C63<0,C63,0) -> 0
...

Sheet Consulta Etapa de Ensino
A1: Município: | B1: Todos os municípios | F1: ← escolha o município e a seleção nas listas. MÉDIA = 2016 a 2025. | N1: Auxiliares (não editar)
A2: Etapa de ensino: | B2: Todas as etapas | F2: Equivalências: Creche ≈ 0-3 · Pré-escola ≈ 4-5 · Anos Iniciais ≈ 6-10 · Anos Finais ≈ 11-14 · Ensino Médio ≈ 15-17 | N2: Índice da seleção | O2: =MATCH($B$2,Listas!$E$2:$E$7,0) -> 1
A3: População: | B3: =IF($B$1="Todos os municípios",SUM(População!$C$2:$C$400),INDEX(População!$C$2:$C$400,MATCH($B$1,População!$B$2:$B$400,0))) -> 11824665 | F3: ← população estimada 2024 | N3: Critério município | O3: =IF($B$1="Todos os municípios","*",$B$1) -> *
B4: PÚBLICO | C4: PUB. PERC | D4: FEDERAL | E4: FED. PERC | F4: ESTADUAL | G4: EST. PERC | H4: MUNICIPAL | I4: MUN. PERC | J4: PRIVADO | K4: PRI. PERC | L4: TOTAL | N4: Índice da rede (gráfico) | O4: =MATCH($B$16,Listas!$G$2:$G$7,0) -> 6
A5: 2016 | B5: =D5+F5+H5 -> 1970361 | C5: =IF($L5=0,0,B5/$L5) -> 0.83879022 | D5: =IF($O$2=1,SUMIFS(INDEX(Plan1_Etapas,0,1),Plan1_Ano,$A5,Plan1_Municipio,$O$3,Plan1_Rede,"Federal")+SUMIFS(INDEX(Plan1_Etapas,0,2),Plan1_Ano,$A5,Plan1_Municipio,$O$3,Plan1_Rede,"Federal")+SUMIFS(INDEX(Plan1_Etapas,0,3),Plan1_Ano,$A5,Plan1_Municipio,$O$3,Plan1_Rede,"Federal")+SUMIFS(INDEX(Plan1_Etapas,0,4),Plan1_Ano,$A5,Plan1_Municipio,$O$3,Plan1_Rede,"Federal")+SUMIFS(INDEX(Plan1_Etapas,0,5),Plan1_Ano,$A5,Plan1_Municipio,$O$3,Plan1_Rede,"Federal"),SUMIFS(INDEX(Plan1_Etapas,0,$O$2-1),Plan1_Ano,$A5,Plan1_Municipio,$O$3,Plan1_Rede,"Federal")) -> 7018 | E5: =IF($L5=0,0,D5/$L5) -> 0.0029875895 | F5: =IF($O$2=1,SUMIFS(INDEX(Plan1_Etapas,0,1),Plan1_Ano,$A5,Plan1_Municipio,$O$3,Plan1_Rede,"Estadual")+SUMIFS(INDEX(Plan1_Etapas,0,2),Plan1_Ano,$A5,Plan1_Municipio,$O$3,Plan1_Rede,"Estadual")+SUMIFS(INDEX(Plan1_Etapas,0,3),Plan1_Ano,$A5,Plan1_Municipio,$O$3,Plan1_Rede,"Estadual")+SUMIFS(INDEX(Plan1_Etapas,0,4),Plan1_Ano,$A5,Plan1_Municipio,$O$3,Plan1_Rede,"Estadual")+SUMIFS(INDEX(Plan1_Etapas,0,5),Plan1_Ano,$A5,Plan1_Municipio,$O$3,Plan1_Rede,"Estadual"),SUMIFS(INDEX(Plan1_Etapas,0,$O$2-1),Plan1_Ano,$A5,Plan1_Municipio,$O$3,Plan1_Rede,"Estadual")) -> 942008 | G5: =IF($L5=0,0,F5/$L5) -> 0.40101641 | H5: =IF($O$2=1,SUMIFS(INDEX(Plan1_Etapas,0,1),Plan1_Ano,$A5,Plan1_Municipio,$O$3,Plan1_Rede,"Municipal")+SUMIFS(INDEX(Plan1_Etapas,0,2),Plan1_Ano,$A5,Plan1_Municipio,$O$3,Plan1_Rede,"Municipal")+SUMIFS(INDEX(Plan1_Etapas,0,3),Plan1_Ano,$A5,Plan1_Municipio,$O$3,Plan1_Rede,"Municipal")+SUMIFS(INDEX(Plan1_Etapas,0,4),Plan1_Ano,$A5,Plan1_Municipio,$O$3,Plan1_Rede,"Municipal")+SUMIFS(INDEX(Plan1_Etapas,0,5),Plan1_Ano,$A5,Plan1_Municipio,$O$3,Plan1_Rede,"Municipal"),SUMIFS(INDEX(Plan1_Etapas,0,$O$2-1),Plan1_Ano,$A5,Plan1_Municipio,$O$3,Plan1_Rede,"Municipal")) -> 1021335 | I5: =IF($L5=0,0,H5/$L5) -> 0.43478622 | J5: =IF($O$2=1,SUMIFS(INDEX(Plan1_Etapas,0,1),Plan1_Ano,$A5,Plan1_Municipio,$O$3,Plan1_Rede,"Privada")+SUMIFS(INDEX(Plan1_Etapas,0,2),Plan1_Ano,$A5,Plan1_Municipio,$O$3,Plan1_Rede,"Privada")+SUMIFS(INDEX(Plan1_Etapas,0,3),Plan1_Ano,$A5,Plan1_Municipio,$O$3,Plan1_Rede,"Privada")+SUMIFS(INDEX(Plan1_Etapas,0,4),Plan1_Ano,$A5,Plan1_Municipio,$O$3,Plan1_Rede,"Privada")+SUMIFS(INDEX(Plan1_Etapas,0,5),Plan1_Ano,$A5,Plan1_Municipio,$O$3,Plan1_Rede,"Privada"),SUMIFS(INDEX(Plan1_Etapas,0,$O$2-1),Plan1_Ano,$A5,Plan1_Municipio,$O$3,Plan1_Rede,"Privada")) -> 378690 | K5: =IF($L5=0,0,J5/$L5) -> 0.16120978 | L5: =B5+J5 -> 2349051
A6: 2017 | B6: =D6+F6+H6 -> 1973276 | C6: =IF($L6=0,0,B6/$L6) -> 0.84085623 | D6: =IF($O$2=1,SUMIFS(INDEX(Plan1_Etapas,0,1),Plan1_Ano,$A6,Plan1_Municipio,$O$3,Plan1_Rede,"Federal")+SUMIFS(INDEX(Plan1_Etapas,0,2),Plan1_Ano,$A6,Plan1_Municipio,$O$3,Plan1_Rede,"Federal")+SUMIFS(INDEX(Plan1_Etapas,0,3),Plan1_Ano,$A6,Plan1_Municipio,$O$3,Plan1_Rede,"Federal")+SUMIFS(INDEX(Plan1_Etapas,0,4),Plan1_Ano,$A6,Plan1_Municipio,$O$3,Plan1_Rede,"Federal")+SUMIFS(INDEX(Plan1_Etapas,0,5),Plan1_Ano,$A6,Plan1_Municipio,$O$3,Plan1_Rede,"Federal"),SUMIFS(INDEX(Plan1_Etapas,0,$O$2-1),Plan1_Ano,$A6,Plan1_Municipio,$O$3,Plan1_Rede,"Federal")) -> 8004 | E6: =IF($L6=0,0,D6/$L6) -> 0.0034106802 | F6: =IF($O$2=1,SUMIFS(INDEX(Plan1_Etapas,0,1),Plan1_Ano,$A6,Plan1_Municipio,$O$3,Plan1_Rede,"Estadual")+SUMIFS(INDEX(Plan1_Etapas,0,2),Plan1_Ano,$A6,Plan1_Municipio,$O$3,Plan1_Rede,"Estadual")+SUMIFS(INDEX(Plan1_Etapas,0,3),Plan1_Ano,$A6,Plan1_Municipio,$O$3,Plan1_Rede,"Estadual")+SUMIFS(INDEX(Plan1_Etapas,0,4),Plan1_Ano,$A6,Plan1_Municipio,$O$3,Plan1_Rede,"Estadual")+SUMIFS(INDEX(Plan1_Etapas,0,5),Plan1_Ano,$A6,Plan1_Municipio,$O$3,Plan1_Rede,"Estadual"),SUMIFS(INDEX(Plan1_Etapas,0,$O$2-1),Plan1_Ano,$A6,Plan1_Municipio,$O$3,Plan1_Rede,"Estadual")) -> 931441 | G6: =IF($L6=0,0,F6/$L6) -> 0.39690746 | H6: =IF($O$2=1,SUMIFS(INDEX(Plan1_Etapas,0,1),Plan1_Ano,$A6,Plan1_Municipio,$O$3,Plan1_Rede,"Municipal")+SUMIFS(INDEX(Plan1_Etapas,0,2),Plan1_Ano,$A6,Plan1_Municipio,$O$3,Plan1_Rede,"Municipal")+SUMIFS(INDEX(Plan1_Etapas,0,3),Plan1_Ano,$A6,Plan1_Municipio,$O$3,Plan1_Rede,"Municipal")+SUMIFS(INDEX(Plan1_Etapas,0,4),Plan1_Ano,$A6,Plan1_Municipio,$O$3,Plan1_Rede,"Municipal")+SUMIFS(INDEX(Plan1_Etapas,0,5),Plan1_Ano,$A6,Plan1_Municipio,$O$3,Plan1_Rede,"Municipal"),SUMIFS(INDEX(Plan1_Etapas,0,$O$2-1),Plan1_Ano,$A6,Plan1_Municipio,$O$3,Plan1_Rede,"Municipal")) -> 1033831 | I6: =IF($L6=0,0,H6/$L6) -> 0.44053809 | J6: =IF($O$2=1,SUMIFS(INDEX(Plan1_Etapas,0,1),Plan1_Ano,$A6,Plan1_Municipio,$O$3,Plan1_Rede,"Privada")+SUMIFS(INDEX(Plan1_Etapas,0,2),Plan1_Ano,$A6,Plan1_Municipio,$O$3,Plan1_Rede,"Privada")+SUMIFS(INDEX(Plan1_Etapas,0,3),Plan1_Ano,$A6,Plan1_Municipio,$O$3,Plan1_Rede,"Privada")+SUMIFS(INDEX(Plan1_Etapas,0,4),Plan1_Ano,$A6,Plan1_Municipio,$O$3,Plan1_Rede,"Privada")+SUMIFS(INDEX(Plan1_Etapas,0,5),Plan1_Ano,$A6,Plan1_Municipio,$O$3,Plan1_Rede,"Privada"),SUMIFS(INDEX(Plan1_Etapas,0,$O$2-1),Plan1_Ano,$A6,Plan1_Municipio,$O$3,Plan1_Rede,"Privada")) -> 373470 | K6: =IF($L6=0,0,J6/$L6) -> 0.15914377 | L6: =B6+J6 -> 2346746
A7: 2018 | B7: =D7+F7+H7 -> 1968757 | C7: =IF($L7=0,0,B7/$L7) -> 0.84035939 | D7: =IF($O$2=1,SUMIFS(INDEX(Plan1_Etapas,0,1),Plan1_Ano,$A7,Plan1_Municipio,$O$3,Plan1_Rede,"Federal")+SUMIFS(INDEX(Plan1_Etapas,0,2),Plan1_Ano,$A7,Plan1_Municipio,$O$3,Plan1_Rede,"Federal")+SUMIFS(INDEX(Plan1_Etapas,0,3),Plan1_Ano,$A7,Plan1_Municipio,$O$3,Plan1_Rede,"Federal")+SUMIFS(INDEX(Plan1_Etapas,0,4),Plan1_Ano,$A7,Plan1_Municipio,$O$3,Plan1_Rede,"Federal")+SUMIFS(INDEX(Plan1_Etapas,0,5),Plan1_Ano,$A7,Plan1_Municipio,$O$3,Plan1_Rede,"Federal"),SUMIFS(INDEX(Plan1_Etapas,0,$O$2-1),Plan1_Ano,$A7,Plan1_Municipio,$O$3,Plan1_Rede,"Federal")) -> 9358 | E7: =IF($L7=0,0,D7/$L7) -> 0.0039944407 | F7: =IF($O$2=1,SUMIFS(INDEX(Plan1_Etapas,0,1),Plan1_Ano,$A7,Plan1_Municipio,$O$3,Plan1_Rede,"Estadual")+SUMIFS(INDEX(Plan1_Etapas,0,2),Plan1_Ano,$A7,Plan1_Municipio,$O$3,Plan1_Rede,"Estadual")+SUMIFS(INDEX(Plan1_Etapas,0,3),Plan1_Ano,$A7,Plan1_Municipio,$O$3,Plan1_Rede,"Estadual")+SUMIFS(INDEX(Plan1_Etapas,0,4),Plan1_Ano,$A7,Plan1_Municipio,$O$3,Plan1_Rede,"Estadual")+SUMIFS(INDEX(Plan1_Etapas,0,5),Plan1_Ano,$A7,Plan1_Municipio,$O$3,Plan1_Rede,"Estadual"),SUMIFS(INDEX(Plan1_Etapas,0,$O$2-1),Plan1_Ano,$A7,Plan1_Municipio,$O$3,Plan1_Rede,"Estadual")) -> 913984 | G7: =IF($L7=0,0,F7/$L7) -> 0.39013196 | H7: =IF($O$2=1,SUMIFS(INDEX(Plan1_Etapas,0,1),Plan1_Ano,$A7,Plan1_Municipio,$O$3,Plan1_Rede,"Municipal")+SUMIFS(INDEX(Plan1_Etapas,0,2),Plan1_Ano,$A7,Plan1_Municipio,$O$3,Plan1_Rede,"Municipal")+SUMIFS(INDEX(Plan1_Etapas,0,3),Plan1_Ano,$A7,Plan1_Municipio,$O$3,Plan1_Rede,"Municipal")+SUMIFS(INDEX(Plan1_Etapas,0,4),Plan1_Ano,$A7,Plan1_Municipio,$O$3,Plan1_Rede,"Municipal")+SUMIFS(INDEX(Plan1_Etapas,0,5),Plan1_Ano,$A7,Plan1_Municipio,$O$3,Plan1_Rede,"Municipal"),SUMIFS(INDEX(Plan1_Etapas,0,$O$2-1),Plan1_Ano,$A7,Plan1_Municipio,$O$3,Plan1_Rede,"Municipal")) -> 1045415 | I7: =IF($L7=0,0,H7/$L7) -> 0.44623298 | J7: =IF($O$2=1,SUMIFS(INDEX(Plan1_Etapas,0,1),Plan1_Ano,$A7,Plan1_Municipio,$O$3,Plan1_Rede,"Privada")+SUMIFS(INDEX(Plan1_Etapas,0,2),Plan1_Ano,$A7,Plan1_Municipio,$O$3,Plan1_Rede,"Privada")+SUMIFS(INDEX(Plan1_Etapas,0,3),Plan1_Ano,$A7,Plan1_Municipio,$O$3,Plan1_Rede,"Privada")+SUMIFS(INDEX(Plan1_Etapas,0,4),Plan1_Ano,$A7,Plan1_Municipio,$O$3,Plan1_Rede,"Privada")+SUMIFS(INDEX(Plan1_Etapas,0,5),Plan1_Ano,$A7,Plan1_Municipio,$O$3,Plan1_Rede,"Privada"),SUMIFS(INDEX(Plan1_Etapas,0,$O$2-1),Plan1_Ano,$A7,Plan1_Municipio,$O$3,Plan1_Rede,"Privada")) -> 373999 | K7: =IF($L7=0,0,J7/$L7) -> 0.15964061 | L7: =B7+J7 -> 2342756
A8: 2019 | B8: =D8+F8+H8 -> 1935951 | C8: =IF($L8=0,0,B8/$L8) -> 0.83610357 | D8: =IF($O$2=1,SUMIFS(INDEX(Plan1_Etapas,0,1),Plan1_Ano,$A8,Plan1_Municipio,$O$3,Plan1_Rede,"Federal")+SUMIFS(INDEX(Plan1_Etapas,0,2),Plan1_Ano,$A8,Plan1_Municipio,$O$3,Plan1_Rede,"Federal")+SUMIFS(INDEX(Plan1_Etapas,0,3),Plan1_Ano,$A8,Plan1_Municipio,$O$3,Plan1_Rede,"Federal")+SUMIFS(INDEX(Plan1_Etapas,0,4),Plan1_Ano,$A8,Plan1_Municipio,$O$3,Plan1_Rede,"Federal")+SUMIFS(INDEX(Plan1_Etapas,0,5),Plan1_Ano,$A8,Plan1_Municipio,$O$3,Plan1_Rede,"Federal"),SUMIFS(INDEX(Plan1_Etapas,0,$O$2-1),Plan1_Ano,$A8,Plan1_Municipio,$O$3,Plan1_Rede,"Federal")) -> 9684 | E8: =IF($L8=0,0,D8/$L8) -> 0.0041823512 | F8: =IF($O$2=1,SUMIFS(INDEX(Plan1_Etapas,0,1),Plan1_Ano,$A8,Plan1_Municipio,$O$3,Plan1_Rede,"Estadual")+SUMIFS(INDEX(Plan1_Etapas,0,2),Plan1_Ano,$A8,Plan1_Municipio,$O$3,Plan1_Rede,"Estadual")+SUMIFS(INDEX(Plan1_Etapas,0,3),Plan1_Ano,$A8,Plan1_Municipio,$O$3,Plan1_Rede,"Estadual")+SUMIFS(INDEX(Plan1_Etapas,0,4),Plan1_Ano,$A8,Plan1_Municipio,$O$3,Plan1_Rede,"Estadual")+SUMIFS(INDEX(Plan1_Etapas,0,5),Plan1_Ano,$A8,Plan1_Municipio,$O$3,Plan1_Rede,"Estadual"),SUMIFS(INDEX(Plan1_Etapas,0,$O$2-1),Plan1_Ano,$A8,Plan1_Municipio,$O$3,Plan1_Rede,"Estadual")) -> 880262 | G8: =IF($L8=0,0,F8/$L8) -> 0.38016985 | H8: =IF($O$2=1,SUMIFS(INDEX(Plan1_Etapas,0,1),Plan1_Ano,$A8,Plan1_Municipio,$O$3,Plan1_Rede,"Municipal")+SUMIFS(INDEX(Plan1_Etapas,0,2),Plan1_Ano,$A8,Plan1_Municipio,$O$3,Plan1_Rede,"Municipal")+SUMIFS(INDEX(Plan1_Etapas,0,3),Plan1_Ano,$A8,Plan1_Municipio,$O$3,Plan1_Rede,"Municipal")+SUMIFS(INDEX(Plan1_Etapas,0,4),Plan1_Ano,$A8,Plan1_Municipio,$O$3,Plan1_Rede,"Municipal")+SUMIFS(INDEX(Plan1_Etapas,0,5),Plan1_Ano,$A8,Plan1_Municipio,$O$3,Plan1_Rede,"Municipal"),SUMIFS(INDEX(Plan1_Etapas,0,$O$2-1),Plan1_Ano,$A8,Plan1_Municipio,$O$3,Plan1_Rede,"Municipal")) -> 1046005 | I8: =IF($L8=0,0,H8/$L8) -> 0.45175137 | J8: =IF($O$2=1,SUMIFS(INDEX(Plan1_Etapas,0,1),Plan1_Ano,$A8,Plan1_Municipio,$O$3,Plan1_Rede,"Privada")+SUMIFS(INDEX(Plan1_Etapas,0,2),Plan1_Ano,$A8,Plan1_Municipio,$O$3,Plan1_Rede,"Privada")+SUMIFS(INDEX(Plan1_Etapas,0,3),Plan1_Ano,$A8,Plan1_Municipio,$O$3,Plan1_Rede,"Privada")+SUMIFS(INDEX(Plan1_Etapas,0,4),Plan1_Ano,$A8,Plan1_Municipio,$O$3,Plan1_Rede,"Privada")+SUMIFS(INDEX(Plan1_Etapas,0,5),Plan1_Ano,$A8,Plan1_Municipio,$O$3,Plan1_Rede,"Privada"),SUMIFS(INDEX(Plan1_Etapas,0,$O$2-1),Plan1_Ano,$A8,Plan1_Municipio,$O$3,Plan1_Rede,"Privada")) -> 379493 | K8: =IF($L8=0,0,J8/$L8) -> 0.16389643 | L8: =B8+J8 -> 2315444
A9: 2020 | B9: =D9+F9+H9 -> 1965359 | C9: =IF($L9=0,0,B9/$L9) -> 0.84214886 | D9: =IF($O$2=1,SUMIFS(INDEX(Plan1_Etapas,0,1),Plan1_Ano,$A9,Plan1_Municipio,$O$3,Plan1_Rede,"Federal")+SUMIFS(INDEX(Plan1_Etapas,0,2),Plan1_Ano,$A9,Plan1_Municipio,$O$3,Plan1_Rede,"Federal")+SUMIFS(INDEX(Plan1_Etapas,0,3),Plan1_Ano,$A9,Plan1_Municipio,$O$3,Plan1_Rede,"Federal")+SUMIFS(INDEX(Plan1_Etapas,0,4),Plan1_Ano,$A9,Plan1_Municipio,$O$3,Plan1_Rede,"Federal")+SUMIFS(INDEX(Plan1_Etapas,0,5),Plan1_Ano,$A9,Plan1_Municipio,$O$3,Plan1_Rede,"Federal"),SUMIFS(INDEX(Plan1_Etapas,0,$O$2-1),Plan1_Ano,$A9,Plan1_Municipio,$O$3,Plan1_Rede,"Federal")) -> 9820 | E9: =IF($L9=0,0,D9/$L9) -> 0.0042078327 | F9: =IF($O$2=1,SUMIFS(INDEX(Plan1_Etapas,0,1),Plan1_Ano,$A9,Plan1_Municipio,$O$3,Plan1_Rede,"Estadual")+SUMIFS(INDEX(Plan1_Etapas,0,2),Plan1_Ano,$A9,Plan1_Municipio,$O$3,Plan1_Rede,"Estadual")+SUMIFS(INDEX(Plan1_Etapas,0,3),Plan1_Ano,$A9,Plan1_Municipio,$O$3,Plan1_Rede,"Estadual")+SUMIFS(INDEX(Plan1_Etapas,0,4),Plan1_Ano,$A9,Plan1_Municipio,$O$3,Plan1_Rede,"Estadual")+SUMIFS(INDEX(Plan1_Etapas,0,5),Plan1_Ano,$A9,Plan1_Municipio,$O$3,Plan1_Rede,"Estadual"),SUMIFS(INDEX(Plan1_Etapas,0,$O$2-1),Plan1_Ano,$A9,Plan1_Municipio,$O$3,Plan1_Rede,"Estadual")) -> 905323 | G9: =IF($L9=0,0,F9/$L9) -> 0.38792746 | H9: =IF($O$2=1,SUMIFS(INDEX(Plan1_Etapas,0,1),Plan1_Ano,$A9,Plan1_Municipio,$O$3,Plan1_Rede,"Municipal")+SUMIFS(INDEX(Plan1_Etapas,0,2),Plan1_Ano,$A9,Plan1_Municipio,$O$3,Plan1_Rede,"Municipal")+SUMIFS(INDEX(Plan1_Etapas,0,3),Plan1_Ano,$A9,Plan1_Municipio,$O$3,Plan1_Rede,"Municipal")+SUMIFS(INDEX(Plan1_Etapas,0,4),Plan1_Ano,$A9,Plan1_Municipio,$O$3,Plan1_Rede,"Municipal")+SUMIFS(INDEX(Plan1_Etapas,0,5),Plan1_Ano,$A9,Plan1_Municipio,$O$3,Plan1_Rede,"Municipal"),SUMIFS(INDEX(Plan1_Etapas,0,$O$2-1),Plan1_Ano,$A9,Plan1_Municipio,$O$3,Plan1_Rede,"Municipal")) -> 1050216 | I9: =IF($L9=0,0,H9/$L9) -> 0.45001356 | J9: =IF($O$2=1,SUMIFS(INDEX(Plan1_Etapas,0,1),Plan1_Ano,$A9,Plan1_Municipio,$O$3,Plan1_Rede,"Privada")+SUMIFS(INDEX(Plan1_Etapas,0,2),Plan1_Ano,$A9,Plan1_Municipio,$O$3,Plan1_Rede,"Privada")+SUMIFS(INDEX(Plan1_Etapas,0,3),Plan1_Ano,$A9,Plan1_Municipio,$O$3,Plan1_Rede,"Privada")+SUMIFS(INDEX(Plan1_Etapas,0,4),Plan1_Ano,$A9,Plan1_Municipio,$O$3,Plan1_Rede,"Privada")+SUMIFS(INDEX(Plan1_Etapas,0,5),Plan1_Ano,$A9,Plan1_Municipio,$O$3,Plan1_Rede,"Privada"),SUMIFS(INDEX(Plan1_Etapas,0,$O$2-1),Plan1_Ano,$A9,Plan1_Municipio,$O$3,Plan1_Rede,"Privada")) -> 368384 | K9: =IF($L9=0,0,J9/$L9) -> 0.15785114 | L9: =B9+J9 -> 2333743
A10: 2021 | B10: =D10+F10+H10 -> 1865092 | C10: =IF($L10=0,0,B10/$L10) -> 0.84715567 | D10: =IF($O$2=1,SUMIFS(INDEX(Plan1_Etapas,0,1),Plan1_Ano,$A10,Plan1_Municipio,$O$3,Plan1_Rede,"Federal")+SUMIFS(INDEX(Plan1_Etapas,0,2),Plan1_Ano,$A10,Plan1_Municipio,$O$3,Plan1_Rede,"Federal")+SUMIFS(INDEX(Plan1_Etapas,0,3),Plan1_Ano,$A10,Plan1_Municipio,$O$3,Plan1_Rede,"Federal")+SUMIFS(INDEX(Plan1_Etapas,0,4),Plan1_Ano,$A10,Plan1_Municipio,$O$3,Plan1_Rede,"Federal")+SUMIFS(INDEX(Plan1_Etapas,0,5),Plan1_Ano,$A10,Plan1_Municipio,$O$3,Plan1_Rede,"Federal"),SUMIFS(INDEX(Plan1_Etapas,0,$O$2-1),Plan1_Ano,$A10,Plan1_Municipio,$O$3,Plan1_Rede,"Federal")) -> 8949 | E10: =IF($L10=0,0,D10/$L10) -> 0.004064784 | F10: =IF($O$2=1,SUMIFS(INDEX(Plan1_Etapas,0,1),Plan1_Ano,$A10,Plan1_Municipio,$O$3,Plan1_Rede,"Estadual")+SUMIFS(INDEX(Plan1_Etapas,0,2),Plan1_Ano,$A10,Plan1_Municipio,$O$3,Plan1_Rede,"Estadual")+SUMIFS(INDEX(Plan1_Etapas,0,3),Plan1_Ano,$A10,Plan1_Municipio,$O$3,Plan1_Rede,"Estadual")+SUMIFS(INDEX(Plan1_Etapas,0,4),Plan1_Ano,$A10,Plan1_Municipio,$O$3,Plan1_Rede,"Estadual")+SUMIFS(INDEX(Plan1_Etapas,0,5),Plan1_Ano,$A10,Plan1_Municipio,$O$3,Plan1_Rede,"Estadual"),SUMIFS(INDEX(Plan1_Etapas,0,$O$2-1),Plan1_Ano,$A10,Plan1_Municipio,$O$3,Plan1_Rede,"Estadual")) -> 817876 | G10: =IF($L10=0,0,F10/$L10) -> 0.37149282 | H10: =IF($O$2=1,SUMIFS(INDEX(Plan1_Etapas,0,1),Plan1_Ano,$A10,Plan1_Municipio,$O$3,Plan1_Rede,"Municipal")+SUMIFS(INDEX(Plan1_Etapas,0,2),Plan1_Ano,$A10,Plan1_Municipio,$O$3,Plan1_Rede,"Municipal")+SUMIFS(INDEX(Plan1_Etapas,0,3),Plan1_Ano,$A10,Plan1_Municipio,$O$3,Plan1_Rede,"Municipal")+SUMIFS(INDEX(Plan1_Etapas,0,4),Plan1_Ano,$A10,Plan1_Municipio,$O$3,Plan1_Rede,"Municipal")+SUMIFS(INDEX(Plan1_Etapas,0,5),Plan1_Ano,$A10,Plan1_Municipio,$O$3,Plan1_Rede,"Municipal"),SUMIFS(INDEX(Plan1_Etapas,0,$O$2-1),Plan1_Ano,$A10,Plan1_Municipio,$O$3,Plan1_Rede,"Municipal")) -> 1038267 | I10: =IF($L10=0,0,H10/$L10) -> 0.47159807 | J10: =IF($O$2=1,SUMIFS(INDEX(Plan1_Etapas,0,1),Plan1_Ano,$A10,Plan1_Municipio,$O$3,Plan1_Rede,"Privada")+SUMIFS(INDEX(Plan1_Etapas,0,2),Plan1_Ano,$A10,Plan1_Municipio,$O$3,Plan1_Rede,"Privada")+SUMIFS(INDEX(Plan1_Etapas,0,3),Plan1_Ano,$A10,Plan1_Municipio,$O$3,Plan1_Rede,"Privada")+SUMIFS(INDEX(Plan1_Etapas,0,4),Plan1_Ano,$A10,Plan1_Municipio,$O$3,Plan1_Rede,"Privada")+SUMIFS(INDEX(Plan1_Etapas,0,5),Plan1_Ano,$A10,Plan1_Municipio,$O$3,Plan1_Rede,"Privada"),SUMIFS(INDEX(Plan1_Etapas,0,$O$2-1),Plan1_Ano,$A10,Plan1_Municipio,$O$3,Plan1_Rede,"Privada")) -> 336501 | K10: =IF($L10=0,0,J10/$L10) -> 0.15284433 | L10: =B10+J10 -> 2201593
A11: 2022 | B11: =D11+F11+H11 -> 1961173 | C11: =IF($L11=0,0,B11/$L11) -> 0.84208861 | D11: =IF($O$2=1,SUMIFS(INDEX(Plan1_Etapas,0,1),Plan1_Ano,$A11,Plan1_Municipio,$O$3,Plan1_Rede,"Federal")+SUMIFS(INDEX(Plan1_Etapas,0,2),Plan1_Ano,$A11,Plan1_Municipio,$O$3,Plan1_Rede,"Federal")+SUMIFS(INDEX(Plan1_Etapas,0,3),Plan1_Ano,$A11,Plan1_Municipio,$O$3,Plan1_Rede,"Federal")+SUMIFS(INDEX(Plan1_Etapas,0,4),Plan1_Ano,$A11,Plan1_Municipio,$O$3,Plan1_Rede,"Federal")+SUMIFS(INDEX(Plan1_Etapas,0,5),Plan1_Ano,$A11,Plan1_Municipio,$O$3,Plan1_Rede,"Federal"),SUMIFS(INDEX(Plan1_Etapas,0,$O$2-1),Plan1_Ano,$A11,Plan1_Municipio,$O$3,Plan1_Rede,"Federal")) -> 8672 | E11: =IF($L11=0,0,D11/$L11) -> 0.003723584 | F11: =IF($O$2=1,SUMIFS(INDEX(Plan1_Etapas,0,1),Plan1_Ano,$A11,Plan1_Municipio,$O$3,Plan1_Rede,"Estadual")+SUMIFS(INDEX(Plan1_Etapas,0,2),Plan1_Ano,$A11,Plan1_Municipio,$O$3,Plan1_Rede,"Estadual")+SUMIFS(INDEX(Plan1_Etapas,0,3),Plan1_Ano,$A11,Plan1_Municipio,$O$3,Plan1_Rede,"Estadual")+SUMIFS(INDEX(Plan1_Etapas,0,4),Plan1_Ano,$A11,Plan1_Municipio,$O$3,Plan1_Rede,"Estadual")+SUMIFS(INDEX(Plan1_Etapas,0,5),Plan1_Ano,$A11,Plan1_Municipio,$O$3,Plan1_Rede,"Estadual"),SUMIFS(INDEX(Plan1_Etapas,0,$O$2-1),Plan1_Ano,$A11,Plan1_Municipio,$O$3,Plan1_Rede,"Estadual")) -> 895374 | G11: =IF($L11=0,0,F11/$L11) -> 0.38445575 | H11: =IF($O$2=1,SUMIFS(INDEX(Plan1_Etapas,0,1),Plan1_Ano,$A11,Plan1_Municipio,$O$3,Plan1_Rede,"Municipal")+SUMIFS(INDEX(Plan1_Etapas,0,2),Plan1_Ano,$A11,Plan1_Municipio,$O$3,Plan1_Rede,"Municipal")+SUMIFS(INDEX(Plan1_Etapas,0,3),Plan1_Ano,$A11,Plan1_Municipio,$O$3,Plan1_Rede,"Municipal")+SUMIFS(INDEX(Plan1_Etapas,0,4),Plan1_Ano,$A11,Plan1_Municipio,$O$3,Plan1_Rede,"Municipal")+SUMIFS(INDEX(Plan1_Etapas,0,5),Plan1_Ano,$A11,Plan1_Municipio,$O$3,Plan1_Rede,"Municipal"),SUMIFS(INDEX(Plan1_Etapas,0,$O$2-1),Plan1_Ano,$A11,Plan1_Municipio,$O$3,Plan1_Rede,"Municipal")) -> 1057127 | I11: =IF($L11=0,0,H11/$L11) -> 0.45390927 | J11: =IF($O$2=1,SUMIFS(INDEX(Plan1_Etapas,0,1),Plan1_Ano,$A11,Plan1_Municipio,$O$3,Plan1_Rede,"Privada")+SUMIFS(INDEX(Plan1_Etapas,0,2),Plan1_Ano,$A11,Plan1_Municipio,$O$3,Plan1_Rede,"Privada")+SUMIFS(INDEX(Plan1_Etapas,0,3),Plan1_Ano,$A11,Plan1_Municipio,$O$3,Plan1_Rede,"Privada")+SUMIFS(INDEX(Plan1_Etapas,0,4),Plan1_Ano,$A11,Plan1_Municipio,$O$3,Plan1_Rede,"Privada")+SUMIFS(INDEX(Plan1_Etapas,0,5),Plan1_Ano,$A11,Plan1_Municipio,$O$3,Plan1_Rede,"Privada"),SUMIFS(INDEX(Plan1_Etapas,0,$O$2-1),Plan1_Ano,$A11,Plan1_Municipio,$O$3,Plan1_Rede,"Privada")) -> 367766 | K11: =IF($L11=0,0,J11/$L11) -> 0.15791139 | L11: =B11+J11 -> 2328939
A12: 2023 | B12: =D12+F12+H12 -> 1937448 | C12: =IF($L12=0,0,B12/$L12) -> 0.83566088 | D12: =IF($O$2=1,SUMIFS(INDEX(Plan1_Etapas,0,1),Plan1_Ano,$A12,Plan1_Municipio,$O$3,Plan1_Rede,"Federal")+SUMIFS(INDEX(Plan1_Etapas,0,2),Plan1_Ano,$A12,Plan1_Municipio,$O$3,Plan1_Rede,"Federal")+SUMIFS(INDEX(Plan1_Etapas,0,3),Plan1_Ano,$A12,Plan1_Municipio,$O$3,Plan1_Rede,"Federal")+SUMIFS(INDEX(Plan1_Etapas,0,4),Plan1_Ano,$A12,Plan1_Municipio,$O$3,Plan1_Rede,"Federal")+SUMIFS(INDEX(Plan1_Etapas,0,5),Plan1_Ano,$A12,Plan1_Municipio,$O$3,Plan1_Rede,"Federal"),SUMIFS(INDEX(Plan1_Etapas,0,$O$2-1),Plan1_Ano,$A12,Plan1_Municipio,$O$3,Plan1_Rede,"Federal")) -> 8490 | E12: =IF($L12=0,0,D12/$L12) -> 0.0036619104 | F12: =IF($O$2=1,SUMIFS(INDEX(Plan1_Etapas,0,1),Plan1_Ano,$A12,Plan1_Municipio,$O$3,Plan1_Rede,"Estadual")+SUMIFS(INDEX(Plan1_Etapas,0,2),Plan1_Ano,$A12,Plan1_Municipio,$O$3,Plan1_Rede,"Estadual")+SUMIFS(INDEX(Plan1_Etapas,0,3),Plan1_Ano,$A12,Plan1_Municipio,$O$3,Plan1_Rede,"Estadual")+SUMIFS(INDEX(Plan1_Etapas,0,4),Plan1_Ano,$A12,Plan1_Municipio,$O$3,Plan1_Rede,"Estadual")+SUMIFS(INDEX(Plan1_Etapas,0,5),Plan1_Ano,$A12,Plan1_Municipio,$O$3,Plan1_Rede,"Estadual"),SUMIFS(INDEX(Plan1_Etapas,0,$O$2-1),Plan1_Ano,$A12,Plan1_Municipio,$O$3,Plan1_Rede,"Estadual")) -> 849102 | G12: =IF($L12=0,0,F12/$L12) -> 0.36623503 | H12: =IF($O$2=1,SUMIFS(INDEX(Plan1_Etapas,0,1),Plan1_Ano,$A12,Plan1_Municipio,$O$3,Plan1_Rede,"Municipal")+SUMIFS(INDEX(Plan1_Etapas,0,2),Plan1_Ano,$A12,Plan1_Municipio,$O$3,Plan1_Rede,"Municipal")+SUMIFS(INDEX(Plan1_Etapas,0,3),Plan1_Ano,$A12,Plan1_Municipio,$O$3,Plan1_Rede,"Municipal")+SUMIFS(INDEX(Plan1_Etapas,0,4),Plan1_Ano,$A12,Plan1_Municipio,$O$3,Plan1_Rede,"Municipal")+SUMIFS(INDEX(Plan1_Etapas,0,5),Plan1_Ano,$A12,Plan1_Municipio,$O$3,Plan1_Rede,"Municipal"),SUMIFS(INDEX(Plan1_Etapas,0,$O$2-1),Plan1_Ano,$A12,Plan1_Municipio,$O$3,Plan1_Rede,"Municipal")) -> 1079856 | I12: =IF($L12=0,0,H12/$L12) -> 0.46576394 | J12: =IF($O$2=1,SUMIFS(INDEX(Plan1_Etapas,0,1),Plan1_Ano,$A12,Plan1_Municipio,$O$3,Plan1_Rede,"Privada")+SUMIFS(INDEX(Plan1_Etapas,0,2),Plan1_Ano,$A12,Plan1_Municipio,$O$3,Plan1_Rede,"Privada")+SUMIFS(INDEX(Plan1_Etapas,0,3),Plan1_Ano,$A12,Plan1_Municipio,$O$3,Plan1_Rede,"Privada")+SUMIFS(INDEX(Plan1_Etapas,0,4),Plan1_Ano,$A12,Plan1_Municipio,$O$3,Plan1_Rede,"Privada")+SUMIFS(INDEX(Plan1_Etapas,0,5),Plan1_Ano,$A12,Plan1_Municipio,$O$3,Plan1_Rede,"Privada"),SUMIFS(INDEX(Plan1_Etapas,0,$O$2-1),Plan1_Ano,$A12,Plan1_Municipio,$O$3,Plan1_Rede,"Privada")) -> 381014 | K12: =IF($L12=0,0,J12/$L12) -> 0.16433912 | L12: =B12+J12 -> 2318462
A13: 2024 | B13: =D13+F13+H13 -> 1959421 | C13: =IF($L13=0,0,B13/$L13) -> 0.83319379 | D13: =IF($O$2=1,SUMIFS(INDEX(Plan1_Etapas,0,1),Plan1_Ano,$A13,Plan1_Municipio,$O$3,Plan1_Rede,"Federal")+SUMIFS(INDEX(Plan1_Etapas,0,2),Plan1_Ano,$A13,Plan1_Municipio,$O$3,Plan1_Rede,"Federal")+SUMIFS(INDEX(Plan1_Etapas,0,3),Plan1_Ano,$A13,Plan1_Municipio,$O$3,Plan1_Rede,"Federal")+SUMIFS(INDEX(Plan1_Etapas,0,4),Plan1_Ano,$A13,Plan1_Municipio,$O$3,Plan1_Rede,"Federal")+SUMIFS(INDEX(Plan1_Etapas,0,5),Plan1_Ano,$A13,Plan1_Municipio,$O$3,Plan1_Rede,"Federal"),SUMIFS(INDEX(Plan1_Etapas,0,$O$2-1),Plan1_Ano,$A13,Plan1_Municipio,$O$3,Plan1_Rede,"Federal")) -> 9224 | E13: =IF($L13=0,0,D13/$L13) -> 0.0039222707 | F13: =IF($O$2=1,SUMIFS(INDEX(Plan1_Etapas,0,1),Plan1_Ano,$A13,Plan1_Municipio,$O$3,Plan1_Rede,"Estadual")+SUMIFS(INDEX(Plan1_Etapas,0,2),Plan1_Ano,$A13,Plan1_Municipio,$O$3,Plan1_Rede,"Estadual")+SUMIFS(INDEX(Plan1_Etapas,0,3),Plan1_Ano,$A13,Plan1_Municipio,$O$3,Plan1_Rede,"Estadual")+SUMIFS(INDEX(Plan1_Etapas,0,4),Plan1_Ano,$A13,Plan1_Municipio,$O$3,Plan1_Rede,"Estadual")+SUMIFS(INDEX(Plan1_Etapas,0,5),Plan1_Ano,$A13,Plan1_Municipio,$O$3,Plan1_Rede,"Estadual"),SUMIFS(INDEX(Plan1_Etapas,0,$O$2-1),Plan1_Ano,$A13,Plan1_Municipio,$O$3,Plan1_Rede,"Estadual")) -> 858520 | G13: =IF($L13=0,0,F13/$L13) -> 0.36506373 | H13: =IF($O$2=1,SUMIFS(INDEX(Plan1_Etapas,0,1),Plan1_Ano,$A13,Plan1_Municipio,$O$3,Plan1_Rede,"Municipal")+SUMIFS(INDEX(Plan1_Etapas,0,2),Plan1_Ano,$A13,Plan1_Municipio,$O$3,Plan1_Rede,"Municipal")+SUMIFS(INDEX(Plan1_Etapas,0,3),Plan1_Ano,$A13,Plan1_Municipio,$O$3,Plan1_Rede,"Municipal")+SUMIFS(INDEX(Plan1_Etapas,0,4),Plan1_Ano,$A13,Plan1_Municipio,$O$3,Plan1_Rede,"Municipal")+SUMIFS(INDEX(Plan1_Etapas,0,5),Plan1_Ano,$A13,Plan1_Municipio,$O$3,Plan1_Rede,"Municipal"),SUMIFS(INDEX(Plan1_Etapas,0,$O$2-1),Plan1_Ano,$A13,Plan1_Municipio,$O$3,Plan1_Rede,"Municipal")) -> 1091677 | I13: =IF($L13=0,0,H13/$L13) -> 0.46420779 | J13: =IF($O$2=1,SUMIFS(INDEX(Plan1_Etapas,0,1),Plan1_Ano,$A13,Plan1_Municipio,$O$3,Plan1_Rede,"Privada")+SUMIFS(INDEX(Plan1_Etapas,0,2),Plan1_Ano,$A13,Plan1_Municipio,$O$3,Plan1_Rede,"Privada")+SUMIFS(INDEX(Plan1_Etapas,0,3),Plan1_Ano,$A13,Plan1_Municipio,$O$3,Plan1_Rede,"Privada")+SUMIFS(INDEX(Plan1_Etapas,0,4),Plan1_Ano,$A13,Plan1_Municipio,$O$3,Plan1_Rede,"Privada")+SUMIFS(INDEX(Plan1_Etapas,0,5),Plan1_Ano,$A13,Plan1_Municipio,$O$3,Plan1_Rede,"Privada"),SUMIFS(INDEX(Plan1_Etapas,0,$O$2-1),Plan1_Ano,$A13,Plan1_Municipio,$O$3,Plan1_Rede,"Privada")) -> 392278 | K13: =IF($L13=0,0,J13/$L13) -> 0.16680621 | L13: =B13+J13 -> 2351699
A14: 2025 | B14: =D14+F14+H14 -> 1899668 | C14: =IF($L14=0,0,B14/$L14) -> 0.82825488 | D14: =IF($O$2=1,SUMIFS(INDEX(Plan1_Etapas,0,1),Plan1_Ano,$A14,Plan1_Municipio,$O$3,Plan1_Rede,"Federal")+SUMIFS(INDEX(Plan1_Etapas,0,2),Plan1_Ano,$A14,Plan1_Municipio,$O$3,Plan1_Rede,"Federal")+SUMIFS(INDEX(Plan1_Etapas,0,3),Plan1_Ano,$A14,Plan1_Municipio,$O$3,Plan1_Rede,"Federal")+SUMIFS(INDEX(Plan1_Etapas,0,4),Plan1_Ano,$A14,Plan1_Municipio,$O$3,Plan1_Rede,"Federal")+SUMIFS(INDEX(Plan1_Etapas,0,5),Plan1_Ano,$A14,Plan1_Municipio,$O$3,Plan1_Rede,"Federal"),SUMIFS(INDEX(Plan1_Etapas,0,$O$2-1),Plan1_Ano,$A14,Plan1_Municipio,$O$3,Plan1_Rede,"Federal")) -> 9679 | E14: =IF($L14=0,0,D14/$L14) -> 0.0042200421 | F14: =IF($O$2=1,SUMIFS(INDEX(Plan1_Etapas,0,1),Plan1_Ano,$A14,Plan1_Municipio,$O$3,Plan1_Rede,"Estadual")+SUMIFS(INDEX(Plan1_Etapas,0,2),Plan1_Ano,$A14,Plan1_Municipio,$O$3,Plan1_Rede,"Estadual")+SUMIFS(INDEX(Plan1_Etapas,0,3),Plan1_Ano,$A14,Plan1_Municipio,$O$3,Plan1_Rede,"Estadual")+SUMIFS(INDEX(Plan1_Etapas,0,4),Plan1_Ano,$A14,Plan1_Municipio,$O$3,Plan1_Rede,"Estadual")+SUMIFS(INDEX(Plan1_Etapas,0,5),Plan1_Ano,$A14,Plan1_Municipio,$O$3,Plan1_Rede,"Estadual"),SUMIFS(INDEX(Plan1_Etapas,0,$O$2-1),Plan1_Ano,$A14,Plan1_Municipio,$O$3,Plan1_Rede,"Estadual")) -> 800373 | G14: =IF($L14=0,0,F14/$L14) -> 0.34896247 | H14: =IF($O$2=1,SUMIFS(INDEX(Plan1_Etapas,0,1),Plan1_Ano,$A14,Plan1_Municipio,$O$3,Plan1_Rede,"Municipal")+SUMIFS(INDEX(Plan1_Etapas,0,2),Plan1_Ano,$A14,Plan1_Municipio,$O$3,Plan1_Rede,"Municipal")+SUMIFS(INDEX(Plan1_Etapas,0,3),Plan1_Ano,$A14,Plan1_Municipio,$O$3,Plan1_Rede,"Municipal")+SUMIFS(INDEX(Plan1_Etapas,0,4),Plan1_Ano,$A14,Plan1_Municipio,$O$3,Plan1_Rede,"Municipal")+SUMIFS(INDEX(Plan1_Etapas,0,5),Plan1_Ano,$A14,Plan1_Municipio,$O$3,Plan1_Rede,"Municipal"),SUMIFS(INDEX(Plan1_Etapas,0,$O$2-1),Plan1_Ano,$A14,Plan1_Municipio,$O$3,Plan1_Rede,"Municipal")) -> 1089616 | I14: =IF($L14=0,0,H14/$L14) -> 0.47507237 | J14: =IF($O$2=1,SUMIFS(INDEX(Plan1_Etapas,0,1),Plan1_Ano,$A14,Plan1_Municipio,$O$3,Plan1_Rede,"Privada")+SUMIFS(INDEX(Plan1_Etapas,0,2),Plan1_Ano,$A14,Plan1_Municipio,$O$3,Plan1_Rede,"Privada")+SUMIFS(INDEX(Plan1_Etapas,0,3),Plan1_Ano,$A14,Plan1_Municipio,$O$3,Plan1_Rede,"Privada")+SUMIFS(INDEX(Plan1_Etapas,0,4),Plan1_Ano,$A14,Plan1_Municipio,$O$3,Plan1_Rede,"Privada")+SUMIFS(INDEX(Plan1_Etapas,0,5),Plan1_Ano,$A14,Plan1_Municipio,$O$3,Plan1_Rede,"Privada"),SUMIFS(INDEX(Plan1_Etapas,0,$O$2-1),Plan1_Ano,$A14,Plan1_Municipio,$O$3,Plan1_Rede,"Privada")) -> 393911 | K14: =IF($L14=0,0,J14/$L14) -> 0.17174512 | L14: =B14+J14 -> 2293579
A15: MÉDIA | B15: =AVERAGE(B5:B14) -> 1943650.6 | C15: =IF($L15=0,0,B15/$L15) -> 0.8384305 | D15: =AVERAGE(D5:D14) -> 8889.8 | E15: =IF($L15=0,0,D15/$L15) -> 0.0038347836 | F15: =AVERAGE(F5:F14) -> 879426.3 | G15: =IF($L15=0,0,F15/$L15) -> 0.37935719 | H15: =AVERAGE(H5:H14) -> 1055334.5 | I15: =IF($L15=0,0,H15/$L15) -> 0.45523853 | J15: =AVERAGE(J5:J14) -> 374550.6 | K15: =IF($L15=0,0,J15/$L15) -> 0.1615695 | L15: =AVERAGE(L5:L14) -> 2318201.2
A16: Rede do gráfico: | B16: Total | F16: ="Variação anual da rede "&LOWER($B$16)&" — "&$B$1&" — "&$B$2 -> Variação anual da rede total — Todos os municípios — Todas as etapas
A39: Variação anual das matrículas (%) em relação ao ano anterior
A40: Ano | B40: PÚBLICO | C40: FEDERAL | D40: ESTADUAL | E40: MUNICIPAL | F40: PRIVADO | G40: TOTAL
A41: 2016 | B41: — | C41: — | D41: — | E41: — | F41: — | G41: —
A42: 2017 | B42: =IF(B5=0,"—",B6/B5-1) -> 0.0014794243 | C42: =IF(D5=0,"—",D6/D5-1) -> 0.14049587 | D42: =IF(F5=0,"—",F6/F5-1) -> -0.011217527 | E42: =IF(H5=0,"—",H6/H5-1) -> 0.012234967 | F42: =IF(J5=0,"—",J6/J5-1) -> -0.013784362 | G42: =IF(L5=0,"—",L6/L5-1) -> -0.00098124732
A43: 2018 | B43: =IF(B6=0,"—",B7/B6-1) -> -0.0022901003 | C43: =IF(D6=0,"—",D7/D6-1) -> 0.16916542 | D43: =IF(F6=0,"—",F7/F6-1) -> -0.018741928 | E43: =IF(H6=0,"—",H7/H6-1) -> 0.011204926 | F43: =IF(J6=0,"—",J7/J6-1) -> 0.0014164458 | G43: =IF(L6=0,"—",L7/L6-1) -> -0.0017002266
A44: 2019 | B44: =IF(B7=0,"—",B8/B7-1) -> -0.016663306 | C44: =IF(D7=0,"—",D8/D7-1) -> 0.034836504 | D44: =IF(F7=0,"—",F8/F7-1) -> -0.036895613 | E44: =IF(H7=0,"—",H8/H7-1) -> 0.00056436917 | F44: =IF(J7=0,"—",J8/J7-1) -> 0.014689879 | G44: =IF(L7=0,"—",L8/L7-1) -> -0.011658064
